Workbook

Sheet Read_Me
A1: Microsoft License Cost Allocation Model
A3: Purpose
A4: Allocate total Microsoft license costs to internal cost centres (RS, AFS, Namibia, Mozambique)
A5: based on active licensed users, using per-license SKU allocation aligned with Microsoft invoicing.
A7: How To Use (Monthly)
A8: 1. Complete Invoice_Input: enter invoice total (incl VAT), VAT rate, exchange rate, billing period
A9: 2. Replace License_Raw data with the new month's Microsoft Admin Centre export
A10: 3. Update Employee_Master if there are new starters/leavers
A11: 4. Enter monthly invoice line-item amounts per SKU on SKU_Cost_Input (yellow cells)
A12: 5. CHECK: Verify the Reconciliation section on Division_Summary — variance must be R0.00
A13: 6. Review the Review_Queue for any unresolved user mappings
A14: 7. Send Division_Summary to Finance
... A51: Review_Queue → Unresolved/flagged users requiring attention

Sheet Invoice_Input
A1: Monthly Invoice Input
A2: Complete ALL yellow cells before entering SKU amounts. This is the control sheet for reconciliation.
A4: Billing Period | B4: March 2026 | C4: e.g. March 2026
A5: Invoice Number | B5: INV-0303 | C5: From Microsoft invoice
A6: Invoice Date | B6: 25/03/2026 | C6: Date on the invoice (DD/MM/YYYY)
A7: Snapshot Date | C7: Date the user list was exported from Admin Centre
A9: Invoice Total (incl VAT) ZAR | B9: 60184.38 | C9: Exact Rand total from the invoice including VAT
A10: VAT Rate % | B10: 0.15 | C10: South Africa standard = 15%
A11: Invoice Total (excl VAT) ZAR | B11: =IF(B10=0,0,B9/(1+B10)) | C11: Calculated: =incl / (1 + VAT rate)
A13: Exchange Rate (USD to ZAR) | B13: 0 | C13: Enter 0 if invoice is already in ZAR. Otherwise enter the rate used.
A14: Invoice Total (USD) | B14: 0 | C14: Enter 0 if invoice is in ZAR. Otherwise enter USD total from invoice.
A15: Converted Total (ZAR) | B15: =IF(B13=0,0,B14*B13) | C15: Calculated: USD × rate. If invoice is already ZAR, this is ignored.
A17: SKU Total (excl VAT) ZAR | B17: =SKU_Cost_Input!D17 | C17: Auto-calculated from SKU_Cost_Input — must match Invoice Total excl VAT
A18: Variance (must be R0.00) | B18: =B11-B17 | C18: =Invoice excl VAT − SKU total. RED if non-zero.
A19: Reconciliation Status | B19: =IF(ABS(B18)<0.01,"PASS","FAIL - SKU amounts do not match invoice") | C19: PASS or FAIL

Sheet Employee_Master
A1: Company Email | B1: Employee Name | C1: Employee Code | D1: Department | E1: Department Group | F1: Site | G1: Division | H1: Job Title | I1: Supervisor | J1: Cell Number | K1: Status
A2: a.ludick@wearcheckRS.com | B2: Adri Ludick | C2: WC492 | D2: ARC-NDT | E2: GP Consult | G2: RS | H2: Manager Mechanical | I2: Philip Schutte | J2: 0832816896 | K2: Submitted
A3: adriaanb@wearcheckrs.com | B3: Adriaan Pertus Johannes Bouwer | C3: WC383 | D3: ARC-RCM | E3: WearCheck | F3: KwaZulu Natal | G3: RS | H3: Thermal Manager | I3: Louis Peacock | J3: 0608498504 | K3: Submitted
A4: marshallr@wearcheckrs.com | B4: Ailwel Marshall Rasimphi | C4: WEC094 | D4: ARC-RCM | E4: GP Consult | F4: Valterra - Waterval | G4: RS | H4: Reliability Technician | I4: Riaan de Beer | J4: 0768219444 | K4: Submitted
A5: alex@wearcheckrs.com | B5: Alexander Outram | C5: WEC105 | D5: ARC-RCM | E5: GP Consult | F5: RBMR and PMR | G5: RS | H5: Reliability Technologist | I5: Micheal Pretorius | J5: 0662213616 / 0720164289 | K5: Submitted
A6: allan@wearcheckrs.com | B6: Allan Stuurman | C6: WEC123 | D6: ARC-RCM | E6: GP Consult | F6: Samancor - ECM Tweefontein | G6: RS | H6: Reliability Technologist - Site Suprevisor | I6: Peet Peacock | J6: 0799121301 | K6: Submitted
A7: andree@wearcheck.co.za | B7: André Erasmus | C7: WC511 | D7: ARC-TCA | E7: AFS | G7: AFS | H7: Machinery Inspector / Auditor | I7: Johan Stols | J7: 0833088571 | K7: Submitted
A8: andrew@wearcheckRS.com | B8: Andrew John Walker Robb | C8: WEC103 | D8: ARC-RCM | E8: GP Consult | F8: Remote Centre | G8: RS | H8: ARC Centre Manager | I8: Louis Peacock | J8: 0636504444 | K8: Submitted
A9: annahm@wearcheckrs.com | B9: Annah Seipone Modutwane | C9: WC484 | D9: ARC-RCM | E9: WearCheck | F9: Valterra - Mototolo | G9: RS | H9: Trainee Inspector B5 | I9: Londolani Managa | J9: 0833579812 | K9: Submitted
A10: annemie@wearcheckrs.com | B10: Annemie Willer | C10: WC319 | D10: ARC-RCM | E10: WearCheck | F10: Longmeadow H/O | G10: RS | H10: Divisional Manager | I10: Philip Schutte | J10: 0716096197 | K10: Incomplete
A11: antonio.ehrke@wearcheckrs.com | B11: Antonio Ehrke | C11: WC503 | D11: ARC-RCA | E11: AFS | G11: AFS | H11: RCA Inspector | I11: Roger Henwood | J11: 0834695668 | K11: Submitted
A12: armindo@wearcheckrs.com | B12: Armindo Muchacho | C12: Unknown | D12: ARC-RCM | E12: WearCheck | F12: Mozambique | G12: Mozambique | H12: Site Supervisor | I12: Riaan du Plooy | J12: 258848349643 | K12: Submitted
A13: Arnold@WearCheckRS.com | B13: Arnoldus Johannes van Zyl | C13: WC526 | D13: ARC-TCA | E13: AFS | G13: AFS | H13: Electrical Inspector | I13: Johan Stols | J13: 067412 1369 | K13: Submitted
A14: aubrey@wearcheckRS.com | B14: Aubrey Tshabalala | C14: WEC114 | D14: ARC-RCM | E14: GP Consult | F14: Valterra - Mototolo | G14: RS | H14: Reliability Technologist | I14: Annah Modutwane | J14: 0824871527 | K14: Submitted
A15: N/A | B15: Benedito Timana | C15: Unknown | D15: ARC-RCM | E15: WearCheck | F15: Mozambique | G15: Mozambique | H15: Oil Sampler / Data collector | I15: Riaan du Plooy | J15: 258 879321970 | K15: Submitted
A16: Bianka@WearCheckRS.com | B16: Bianka de Beer | C16: WEC142 | D16: ARC-RCM | E16: GP Consult | F16: Longmeadow H/O | G16: RS | H16: Administrator | I16: Megan Salzwedel | J16: 0740317981 | K16: Submitted
A17: chicco@wearcheckrs.com | B17: Chicco Fransisco Tivane | C17: WC380 | D17: ARC-RCM | E17: WearCheck | F17: Steelpoort | G17: RS | H17: Reliability Technologist | I17: Londolani Managa | J17: 0818190051 | K17: Submitted
A18: chrism@wearcheckrs.com | B18: Chris Mostert | C18: WEC100 | D18: ARC-RCM | E18: GP Consult | F18: Springs | G18: RS | H18: Reliability Analyst | I18: Eddie Pieterse Snr | J18: 0636922876 | K18: Submitted
A19: chrstene@wearcheckrs.com | B19: Christene Smal | C19: WC285 | D19: ARC-RCM | E19: WearCheck | F19: Longmeadow H/O | G19: RS | H19: RS Administrator | I19: Megan Salzwedel | J19: 0720591125 | K19: Submitted
A20: cj@wearcheckrs.com | B20: CJ Woller | C20: WEC120 | D20: ARC-RCM | E20: GP Consult | F20: RBMR and PMR | G20: RS | H20: Reliability Technician | I20: Michael Preotrius | J20: 0835965562 | K20: Submitted
A21: colleen.pyper@WearCheckRS.com | B21: Colleen Pyper | C21: WC486 | D21: AFS | E21: AFS | G21: AFS | H21: Admin and Finance Assistant | I21: Adri Ludick | J21: 0662916811 | K21: Submitted
A22: greeffm@wearcheck.co.za | B22: Daniel Greef Meintjies | C22: WC528 | D22: ARC-NDT | E22: AFS | G22: AFS | H22: Inspector (Lifting and NDT) | I22: Adri Ludick | J22: 0674121318 | K22: Submitted
A23: daniel@wearcheckrs.com | B23: Tshegofatsho Daniel Molapo | C23: WC402 | D23: ARC-RCM | E23: GP Consult | F23: Valterra - Mototolo | G23: RS | H23: Reliability Technologist | I23: Annah Modutwane | J23: 0828023079 | K23: Submitted
A24: David@wearcheckrs.com | B24: David Viljoen | C24: WEC081 | D24: ARC-RCM | E24: GP Consult | F24: Roamer | G24: RS | H24: Precision Maintenance Technologist | I24: Peet Peacock | J24: 0810106409 | K24: Submitted
A25: davidl@wearcheckrs.com | B25: David Lipague | C25: Unknown | D25: ARC-RCM | E25: WearCheck | F25: Mozambique | G25: Mozambique | H25: Reliability Technician | I25: Riaan du Plooy | J25: 258847817888 | K25: Submitted
A26: deon@wearcheckrs.com | B26: Deon Gaarkeuken | C26: WC358 | D26: ARC-RCM | E26: WearCheck | F26: Roamer | G26: RS | H26: ARC Reliability Specialist | I26: Andrew Robb | J26: 0712524040 | K26: Submitted
A27: desmond@wearcheckrs.com | B27: Desmond Ngomane | C27: WEC086 | D27: ARC-RCM | E27: GP Consult | F27: Valterra - Mototolo | G27: RS | H27: Reliability Technologist | I27: Annah Modutwane | J27: 0796083125 | K27: Submitted
A28: dian@wearcheckrs.com | B28: Dian Leff | C28: WCN008 | D28: ARC-RCM | E28: WearCheck | F28: Namibia | G28: Namibia | H28: Reliability Technician | I28: Rohan Willer | J28: 0817614612 | K28: Submitted
A29: Douglas@WearcheckRS.com | B29: Douglas Prout-Jones | C29: WEC119 | D29: ARC-RCM | E29: GP Consult | F29: Valterra - Waterval | G29: RS | H29: Reliability Technician | I29: Riaan de Beer | J29: 0832855788 / 0823125521 | K29: Submitted
A30: eben@wearcheckrs.com | B30: Eben Prinsloo | C30: WEC122 | D30: ARC-RCM | E30: GP Consult | F30: Roamer | G30: RS | H30: Reliability Technologist | I30: Edward Pieterse Jnr | J30: 0824146986 | K30: Submitted
A31: edwardfp@wearcheckrs.com | B31: Edward Frederick IV Pieterse | C31: WC274 | D31: ARC-RCM | E31: WearCheck | F31: Longmeadow H/O | G31: RS | H31: Operations Manager | I31: Annemie Willer | J31: 0837930923 | K31: Submitted
A32: edwin@wearcheckrs.com | B32: Edwin Ashley Gibbons | C32: WEC138 | D32: ARC-TCA | E32: AFS | G32: AFS | H32: ARC TC Machinery Inspector | I32: Johan Stols | J32: 0725336075 | K32: Submitted
A33: ethel.mienie@WearCheckRS.com | B33: Ethel Mienie | C33: WC488 | D33: AFS | E33: AFS | G33: AFS | H33: Administration Assistant | I33: Adri Ludick | J33: 0660215452 | K33: Submitted
A34: epieterse@wearcheckrs.com | B34: Edward Pieterse | C34: WC271 | D34: ARC-RCM | E34: WearCheck | F34: Springs | G34: RS | H34: ARC Reliability Specialist | I34: Peet Peacock | J34: 0829057637 | K34: Submitted
A35: eugene@wearcheckrs.com | B35: Eugene Scheepers | C35: WEC090 | D35: ARC-RCM | E35: GP Consult | F35: Neopak - Rosslyn | G35: RS | H35: Reliability Technician | I35: Francois Pretorius | J35: 0790542385 | K35: Submitted
A36: evertv@wearcheck.co.za | B36: Evert Viljoen | C36: WC497 | D36: ARC-NDT | E36: AFS | G36: AFS | H36: Senior Machinery Inspector | I36: Adri Ludick | J36: 0795284219 | K36: Submitted
A37: Franciosp@wearcheckRS.com | B37: Michael Francios Pretorius | C37: WEC080 | D37: ARC-RCM | E37: GP Consult | F37: Neopak - Rosslyn | G37: RS | H37: Reliability Analyst | I37: Peet Peacock | J37: 0832773047 | K37: Submitted
A38: francoisve@wearcheckrs.com | B38: Francois Jacobus van Eeden | C38: WC287 | D38: ARC-RCM | E38: WearCheck | F38: Remote Centre | G38: RS | H38: Condition Monitoring Specialist | I38: Andrew Robb | J38: 0828023072 | K38: Submitted
A39: francoisp@wearcheckrs.com | B39: Jozua Francois Joubert Pienaar | C39: WEC111 | D39: ARC-RCM | E39: GP Consult | F39: KwaZulu Natal - Hillside | G39: RS | H39: Reliability Analyst | I39: Peet Peacock | J39: 0785618579 | K39: Submitted
A40: Freddy-Ben@wearcheckRS.com | B40: Freddy-Ben Gariseb | C40: WCN004 | D40: ARC-RCM | E40: WearCheck | F40: Namibia | G40: Namibia | H40: Reliability Technician | I40: Rohan Willer | J40: 264813707010 | K40: Submitted
...

Sheet License_Raw
A1: Display Name | B1: User Principal Name | C1: Licenses
A2: Admin | B2: admin@WearCheckRS.com | C2: Microsoft Defender for Office 365 (Plan 2)+Microsoft Fabric (Free)+Microsoft 365 E3
A3: Adri Ludick | B3: A.Ludick@WearCheckRS.com | C3: Microsoft 365 Business Premium+Microsoft Copilot Studio Viral Trial+Microsoft Defender for Office 365 (Plan 2)+Microsoft Power Automate Free
A4: Adri Ludick Old | B4: Adri.ludick@WearCheckRS.com | C4: Microsoft Defender for Office 365 (Plan 2)+Microsoft Power Automate Free+Microsoft 365 Business Standard
A5: Adriaan Bouwer | B5: adriaanb@WearCheckRS.com | C5: Microsoft Defender for Office 365 (Plan 2)+Microsoft Power Automate Free+Microsoft 365 Business Standard+Microsoft Fabric (Free)
A6: AFS Application | B6: afs_app@WearCheckRS.com | C6: Microsoft Power Automate Free+Exchange Online (Plan 1)
A7: Alex Outram | B7: Alex@WearCheckRS.com | C7: Microsoft Defender for Office 365 (Plan 2)+Microsoft Power Automate Free+Microsoft Fabric (Free)+Microsoft 365 Business Standard
A8: Allan Stuurman | B8: Allan@WearCheckRS.com | C8: Microsoft Defender for Office 365 (Plan 2)+Microsoft 365 Business Standard
A9: Andrew Robb | B9: Andrew@wearcheckrs.com | C9: Microsoft 365 Business Premium+Microsoft Defender for Office 365 (Plan 2)+Microsoft Fabric (Free)
A10: Annah Modutwane | B10: annahm@WearCheckRS.com | C10: Microsoft Defender for Office 365 (Plan 2)+Microsoft Power Automate Free+Microsoft Fabric (Free)+Microsoft 365 Business Standard
A11: Annemie Willer | B11: annemie@WearCheckRS.com | C11: Microsoft Defender for Office 365 (Plan 2)+Power BI Premium Per User+Microsoft Copilot Studio Viral Trial+Microsoft Power Apps Plan 2 Trial+Microsoft 365 E3+Microsoft Fabric (Free)+Microsoft Power Automate Free
A12: Antonio Ehrke | B12: Antonio.Ehrke@WearCheckRS.com | C12: Microsoft Defender for Office 365 (Plan 2)+Microsoft 365 Business Standard
... A148: Wihan Willer | B148: Wihan@WearCheckRS.com | C148: Microsoft Defender for Office 365 (Plan 2)+Microsoft 365 Business Standard

Sheet User_Match
A1: Licensed Display Name | B1: Licensed Email | C1: Matched Employee Name | D1: Candidate Employee Email | E1: Employee Number | F1: Division | G1: Match Status | H1: Confidence | I1: Review Required | J1: User Status | K1: Mapping Note | L1: License SKU Count | M1: All Licenses Raw | N1: Duplicate Flag
A2: Admin | B2: admin@WearCheckRS.com | F2: RS | G2: Mapped by rule | H2: High | I2: No | J2: Active | K2: Generic/shared/service account defaulted to RS per instruction | L2: 3 | M2: Microsoft Defender for Office 365 (Plan 2)+Microsoft Fabric (Free)+Microsoft 365 E3
A3: Adri Ludick | B3: A.Ludick@WearCheckRS.com | C3: Adri Ludick | D3: a.ludick@wearcheckRS.com | E3: WC492 | F3: RS | G3: Matched | H3: High | I3: No | J3: Active | K3: Exact company email match | L3: 4 | M3: Microsoft 365 Business Premium+Microsoft Copilot Studio Viral Trial+Microsoft Defender for Office 365 (Plan 2)+Microsoft Power Automate Free
A4: Adri Ludick Old | B4: Adri.ludick@WearCheckRS.com | F4: RS | G4: Ex-Employee | H4: High | I4: No | J4: Ex-Employee | K4: Old account — new email A.Ludick@WearCheckRS.com is active. FLAG: Remove this licence. | L4: 3 | M4: Microsoft Defender for Office 365 (Plan 2)+Microsoft Power Automate Free+Microsoft 365 Business Standard
A5: Adriaan Bouwer | B5: adriaanb@WearCheckRS.com | C5: Adriaan Pertus Johannes Bouwer | D5: adriaanb@wearcheckrs.com | E5: WC383 | F5: RS | G5: Matched | H5: High | I5: No | J5: Active | K5: Exact company email match | L5: 4 | M5: Microsoft Defender for Office 365 (Plan 2)+Microsoft Power Automate Free+Microsoft 365 Business Standard+Microsoft Fabric (Free)
A6: AFS Application | B6: afs_app@WearCheckRS.com | F6: AFS | G6: Mapped by rule | H6: High | I6: No | J6: Active | K6: Generic/shared/service account defaulted to RS per instruction | L6: 2 | M6: Microsoft Power Automate Free+Exchange Online (Plan 1)
A7: Alex Outram | B7: Alex@WearCheckRS.com | C7: Alexander Outram | D7: alex@wearcheckrs.com | E7: WEC105 | F7: RS | G7: Matched | H7: High | I7: No | J7: Active | K7: Exact company email match | L7: 4 | M7: Microsoft Defender for Office 365 (Plan 2)+Microsoft Power Automate Free+Microsoft Fabric (Free)+Microsoft 365 Business Standard
A8: Allan Stuurman | B8: Allan@WearCheckRS.com | C8: Allan Stuurman | D8: allan@wearcheckrs.com | E8: WEC123 | F8: RS | G8: Matched | H8: High | I8: No | J8: Active | K8: Exact company email match | L8: 2 | M8: Microsoft Defender for Office 365 (Plan 2)+Microsoft 365 Business Standard
A9: Andrew Robb | B9: Andrew@wearcheckrs.com | C9: Andrew John Walker Robb | D9: andrew@wearcheckRS.com | E9: WEC103 | F9: RS | G9: Matched | H9: High | I9: No | J9: Active | K9: Exact company email match | L9: 3 | M9: Microsoft 365 Business Premium+Microsoft Defender for Office 365 (Plan 2)+Microsoft Fabric (Free)
A10: Annah Modutwane | B10: annahm@WearCheckRS.com | C10: Annah Seipone Modutwane | D10: annahm@wearcheckrs.com | E10: WC484 | F10: RS | G10: Matched | H10: High | I10: No | J10: Active | K10: Exact company email match | L10: 4 | M10: Microsoft Defender for Office 365 (Plan 2)+Microsoft Power Automate Free+Microsoft Fabric (Free)+Microsoft 365 Business Standard
A11: Annemie Willer | B11: annemie@WearCheckRS.com | C11: Annemie Willer | D11: annemie@wearcheckrs.com | E11: WC319 | F11: RS | G11: Matched | H11: High | I11: No | J11: Active | K11: Exact company email match | L11: 7 | M11: Microsoft Defender for Office 365 (Plan 2)+Power BI Premium Per User+Microsoft Copilot Studio Viral Trial+Microsoft Power Apps Plan 2 Trial+Microsoft 365 E3+Microsoft Fabric (Free)+Microsoft Power Automate Free
A12: Antonio Ehrke | B12: Antonio.Ehrke@WearCheckRS.com | C12: Antonio Ehrke | D12: antonio.ehrke@wearcheckrs.com | E12: WC503 | F12: AFS | G12: Matched | H12: High | I12: No | J12: Active | K12: Exact company email match | L12: 2 | M12: Microsoft Defender for Office 365 (Plan 2)+Microsoft 365 Business Standard
A13: Armindo Mucacho | B13: Armindo@WearCheckRS.com | C13: Armindo Muchacho | D13: armindo@wearcheckrs.com | E13: Unknown | F13: Mozambique | G13: Matched | H13: High | I13: No | J13: Active | K13: Exact company email match | L13: 3 | M13: Microsoft Defender for Office 365 (Plan 2)+Microsoft Fabric (Free)+Microsoft 365 Business Standard
A14: Arnold van Zyl | B14: Arnold@WearCheckRS.com | C14: Arnoldus Johannes van Zyl | D14: Arnold@WearCheckRS.com | E14: WC526 | F14: AFS | G14: Matched | H14: High | I14: No | J14: Active | K14: Exact company email match | L14: 2 | M14: Microsoft Defender for Office 365 (Plan 2)+Microsoft 365 Business Standard
A15: Aubrey Tshabalala | B15: Aubrey@WearCheckRS.com | C15: Aubrey Tshabalala | D15: aubrey@wearcheckRS.com | E15: WEC114 | F15: RS | G15: Matched | H15: High | I15: No | J15: Active | K15: Exact company email match | L15: 2 | M15: Microsoft Defender for Office 365 (Plan 2)+Microsoft 365 Business Standard
A16: Bernard Lopi Molangoane | B16: lopi@WearCheckRS.com | C16: Bernard Lopi Molangoane | D16: lopim@wearcheck.co.za | E16: WC269 | F16: RS | G16: Matched | H16: Medium | I16: No | J16: Active | K16: Matched via exact name | L16: 2 | M16: Microsoft Defender for Office 365 (Plan 2)+Microsoft 365 Business Standard
A17: Betty Monyepao | B17: betty@WearCheckRS.com | C17: Mmatapa Betty Monyepao | D17: betty@wearcheckrs.com | E17: WC465 | F17: RS | G17: Matched | H17: High | I17: No | J17: Active | K17: Exact company email match | L17: 2 | M17: Microsoft Defender for Office 365 (Plan 2)+Microsoft 365 Business Standard
A18: Bianka De Beer | B18: Bianka@WearCheckRS.com | C18: Bianka de Beer | D18: Bianka@WearCheckRS.com | E18: WEC142 | F18: RS | G18: Matched | H18: High | I18: No | J18: Active | K18: Exact company email match | L18: 9 | M18: Microsoft Power Automate Free+Microsoft Power Apps Plan 2 Trial+Microsoft Fabric (Free)+Microsoft Copilot Studio Viral Trial+Microsoft Power Apps for Developer+Power Pages vTrial for Makers+Microsoft Defender for Office 365 (Plan 2)+Dynamics 365 Customer Insights Self-Service+Microsoft 365 Business Premium
A19: Boitumelo Makgamatha | B19: Boitumelo@WearCheckRS.com | F19: RS | G19: Confirmed | H19: High | I19: No | J19: Active | K19: User now added to employee master (reviewed) | L19: 2 | M19: Microsoft Defender for Office 365 (Plan 2)+Microsoft 365 Business Standard
A20: Chicco Tivane | B20: chicco@WearCheckRS.com | C20: Chicco Fransisco Tivane | D20: chicco@wearcheckrs.com | E20: WC380 | F20: RS | G20: Matched | H20: High | I20: No | J20: Active | K20: Exact company email match | L20: 2 | M20: Microsoft Defender for Office 365 (Plan 2)+Microsoft 365 Business Standard
A21: Chris Mostert | B21: ChrisM@wearcheckrs.com | C21: Chris Mostert | D21: chrism@wearcheckrs.com | E21: WEC100 | F21: RS | G21: Matched | H21: High | I21: No | J21: Active | K21: Exact company email match | L21: 2 | M21: Microsoft Defender for Office 365 (Plan 2)+Microsoft 365 Business Standard
A22: Christene Fourie | B22: Christene@WearCheckRS.com | F22: RS | G22: Confirmed | H22: High | I22: No | J22: Active | K22: Confirmed email alias match to chrstene@wearcheckrs.com (reviewed) | L22: 3 | M22: Microsoft Defender for Office 365 (Plan 2)+Microsoft Power Automate Free+Microsoft 365 Business Standard
A23: Christian Geel | B23: Christian@WearCheckRS.com | F23: RS | G23: Ex-Employee | H23: High | I23: No | J23: Ex-Employee | K23: No longer an employee. FLAG: Remove licence. | L23: 2 | M23: Microsoft Fabric (Free)+Microsoft Power Automate Free
A24: Christie | B24: christie.samancor@WearCheckRS.com | F24: RS | G24: Management Review | H24: Low | I24: Yes | J24: Management Review | K24: Not an employee — has free Fabric licence only. Flagged for management review. | L24: 1 | M24: Microsoft Fabric (Free)
A25: CJ Woller | B25: cj@WearCheckRS.com | C25: CJ Woller | D25: cj@wearcheckrs.com | E25: WEC120 | F25: RS | G25: Matched | H25: High | I25: No | J25: Active | K25: Exact company email match | L25: 3 | M25: Microsoft Defender for Office 365 (Plan 2)+Microsoft Power Automate Free+Microsoft 365 Business Standard
A26: Colleen Pyper | B26: colleen.pyper@WearCheckRS.com | C26: Colleen Pyper | D26: colleen.pyper@WearCheckRS.com | E26: WC486 | F26: AFS | G26: Matched | H26: High | I26: No | J26: Active | K26: Exact company email match | L26: 3 | M26: Microsoft Defender for Office 365 (Plan 2)+Microsoft Power Automate Free+Microsoft 365 Business Standard
A27: Daniel Molapo | B27: daniel@WearCheckRS.com | C27: Tshegofatsho Daniel Molapo | D27: daniel@wearcheckrs.com | E27: WC402 | F27: RS | G27: Matched | H27: High | I27: No | J27: Active | K27: Exact company email match | L27: 4 | M27: Microsoft Defender for Office 365 (Plan 2)+Microsoft 365 E3+Microsoft Fabric (Free)+Microsoft Power Automate Free
A28: David Lipange | B28: DavidL@WearCheckRS.com | C28: David Lipague | D28: davidl@wearcheckrs.com | E28: Unknown | F28: Mozambique | G28: Matched | H28: High | I28: No | J28: Active | K28: Exact company email match | L28: 3 | M28: Microsoft Defender for Office 365 (Plan 2)+Microsoft Fabric (Free)+Microsoft 365 Business Standard
A29: David Viljoen | B29: David@WearCheckRS.com | C29: David Viljoen | D29: David@wearcheckrs.com | E29: WEC081 | F29: RS | G29: Matched | H29: High | I29: No | J29: Active | K29: Exact company email match | L29: 4 | M29: Microsoft Defender for Office 365 (Plan 2)+Microsoft Fabric (Free)+Microsoft 365 Business Standard+Microsoft Power Automate Free
A30: Deon Gaarkeuken | B30: Deon@WearCheckRS.com | C30: Deon Gaarkeuken | D30: deon@wearcheckrs.com | E30: WC358 | F30: RS | G30: Matched | H30: High | I30: No | J30: Active | K30: Exact company email match | L30: 5 | M30: Microsoft Defender for Office 365 (Plan 2)+Power BI Premium Per User+Microsoft 365 E3+Microsoft Fabric (Free)+Microsoft Power Automate Free
A31: Desmond Ngomane | B31: desmond@WearCheckRS.com | C31: Desmond Ngomane | D31: desmond@wearcheckrs.com | E31: WEC086 | F31: RS | G31: Matched | H31: High | I31: No | J31: Active | K31: Exact company email match | L31: 3 | M31: Microsoft Defender for Office 365 (Plan 2)+Microsoft Fabric (Free)+Microsoft 365 Business Standard
A32: Dian Leff | B32: dian@WearCheckRS.com | C32: Dian Leff | D32: dian@wearcheckrs.com | E32: WCN008 | F32: Namibia | G32: Matched | H32: High | I32: No | J32: Active | K32: Exact company email match | L32: 2 | M32: Microsoft Defender for Office 365 (Plan 2)+Microsoft 365 Business Standard
A33: Douglas Prout-Jones | B33: douglas@WearCheckRS.com | C33: Douglas Prout-Jones | D33: Douglas@WearcheckRS.com | E33: WEC119 | F33: RS | G33: Matched | H33: High | I33: No | J33: Active | K33: Exact company email match | L33: 3 | M33: Microsoft Defender for Office 365 (Plan 2)+Microsoft Power Automate Free+Microsoft 365 Business Standard
A34: Eben Prinsloo | B34: eben@WearCheckRS.com | C34: Eben Prinsloo | D34: eben@wearcheckrs.com | E34: WEC122 | F34: RS | G34: Matched | H34: High | I34: No | J34: Active | K34: Exact company email match | L34: 3 | M34: Microsoft Defender for Office 365 (Plan 2)+Microsoft 365 Business Standard+Microsoft Fabric (Free)
A35: Edward Pieterse Jnr | B35: edwardfp@WearCheckRS.com | C35: Edward Frederick IV Pieterse | D35: edwardfp@wearcheckrs.com | E35: WC274 | F35: RS | G35: Matched | H35: High | I35: No | J35: Active | K35: Exact company email match | L35: 5 | M35: Microsoft Defender for Office 365 (Plan 2)+Microsoft Power Apps for Developer+Microsoft 365 E3+Microsoft Fabric (Free)+Microsoft Power Automate Free
A36: Edward Pieterse Snr | B36: epieterse@wearcheckrs.com | C36: Edward Pieterse | D36: epieterse@wearcheckrs.com | E36: WC271 | F36: RS | G36: Matched | H36: High | I36: No | J36: Active | K36: Exact company email match | L36: 4 | M36: Microsoft 365 Business Premium+Microsoft Defender for Office 365 (Plan 2)+Microsoft Power Automate Free+Microsoft Fabric (Free)
... A40: Evert Viljoen | B40: Evert@WearCheckRS.com | C40: Evert Viljoen | D40: evertv@wearcheck.co.za | E40: WC497 | F40: AFS | G40: Matched | H40: Medium | I40: No | J40: Active | K40: Matched via exact name | L40: 2 | M40: Microsoft Defender for Office 365 (Plan 2)+Microsoft 365 Business Premium
A41: FLIRIRVM1 | B41: flirirvm1@WearCheckRS.com | F41: RS | G41: Mapped by rule | H41: High | I41: No | J41: Active | K41: Generic/shared/service account defaulted to RS per instruction | L41: 2 | M41: Microsoft Defender for Office 365 (Plan 2)+Microsoft 365 Business Standard
A42: flirirvm2 | B42: flirirvm2@WearCheckRS.com | F42: RS | G42: Mapped by rule | H42: High | I42: No | J42: Active | K42: Generic/shared/service account defaulted to RS per instruction | L42: 3 | M42: Microsoft Defender for Office 365 (Plan 2)+Microsoft Fabric (Free)+Microsoft 365 Business Standard
A43: flirirvm3 | B43: flirirvm3@WearCheckRS.com | F43: RS | G43: Mapped by rule | H43: High | I43: No | J43: Active | K43: Generic/shared/service account defaulted to RS per instruction | L43: 3 | M43: Microsoft Defender for Office 365 (Plan 2)+Microsoft Fabric (Free)+Microsoft 365 Business Standard
...

Sheet SKU_Cost_Input
A1: SKU | B1: Active Users | C1: Billing Hint | D1: Monthly Invoice Amount (excl VAT, ZAR) | E1: Unit Cost Per User (excl VAT) | F1: VAT Amount | G1: Total incl VAT | H1: Notes | I1: Invoice Qty | J1: Qty Variance (Admin − Invoice) | K1: Variance Note
A2: Microsoft Defender for Office 365 (Plan 2) | B2: 130 | C2: Likely billable | D2: 10892.7 | E2: =IF(B2=0,0,D2/B2) | F2: =D2*Invoice_Input!B10 | G2: =D2+F2 | H2: Pre-filled from Invoice INV-0303 (invoice-only SKU — not in admin export) | I2: 130 | J2: 0 | K2: Match
A3: Microsoft 365 Business Standard | B3: 100 | C3: Likely billable | D3: 20326.35 | E3: =IF(B3=0,0,D3/B3) | F3: =D3*Invoice_Input!B10 | G3: =D3+F3 | H3: Pre-filled from Invoice INV-0303 (invoice-only SKU — not in admin export) | I3: 97 | J3: 3 | K3: Admin has 3 more — likely added after invoice billing date
A4: Microsoft Power Automate Free | B4: 52 | C4: Likely free / trial | D4: 0 | E4: =IF(B4=0,0,D4/B4) | F4: =D4*Invoice_Input!B10 | G4: =D4+F4 | H4: Free/trial — R0.00 pre-filled (no invoice cost expected) | I4: N/A | J4: N/A | K4: Not on invoice (free/trial)
A5: Microsoft Fabric (Free) | B5: 50 | C5: Likely free / trial | D5: 0 | E5: =IF(B5=0,0,D5/B5) | F5: =D5*Invoice_Input!B10 | G5: =D5+F5 | H5: Free/trial — R0.00 pre-filled (no invoice cost expected) | I5: N/A | J5: N/A | K5: Not on invoice (free/trial)
A6: Microsoft 365 Business Premium | B6: 21 | C6: Likely billable | D6: 8479.64 | E6: =IF(B6=0,0,D6/B6) | F6: =D6*Invoice_Input!B10 | G6: =D6+F6 | H6: Pre-filled from Invoice INV-0303 (invoice-only SKU — not in admin export) | I6: 23 | J6: -2 | K6: Invoice has 2 more — users may have been removed after billing
A7: Microsoft 365 E3 | B7: 14 | C7: Likely billable | D7: 9049.35 | E7: =IF(B7=0,0,D7/B7) | F7: =D7*Invoice_Input!B10 | G7: =D7+F7 | H7: Pre-filled from Invoice INV-0303 (invoice-only SKU — not in admin export) | I7: 15 | J7: -1 | K7: Invoice has 1 more — users may have been removed after billing
A8: Microsoft Copilot Studio Viral Trial | B8: 7 | C8: Likely free / trial | D8: 0 | E8: =IF(B8=0,0,D8/B8) | F8: =D8*Invoice_Input!B10 | G8: =D8+F8 | H8: Free/trial — R0.00 pre-filled (no invoice cost expected) | I8: N/A | J8: N/A | K8: Not on invoice (free/trial)
A9: Microsoft Power Apps Plan 2 Trial | B9: 6 | C9: Likely free / trial | D9: 0 | E9: =IF(B9=0,0,D9/B9) | F9: =D9*Invoice_Input!B10 | G9: =D9+F9 | H9: Free/trial — R0.00 pre-filled (no invoice cost expected) | I9: N/A | J9: N/A | K9: Not on invoice (free/trial)
A10: Microsoft Power Apps for Developer | B10: 6 | C10: Likely billable | D10: 0 | E10: =IF(B10=0,0,D10/B10) | F10: =D10*Invoice_Input!B10 | G10: =D10+F10 | H10: Enter the excl-VAT invoice amount for this SKU line item | I10: N/A | J10: N/A | K10: Not on invoice (free/trial)
A11: Power BI Premium Per User | B11: 6 | C11: Likely billable | D11: 2815.33 | E11: =IF(B11=0,0,D11/B11) | F11: =D11*Invoice_Input!B10 | G11: =D11+F11 | H11: Pre-filled from Invoice INV-0303 (invoice-only SKU — not in admin export) | I11: 7 | J11: -1 | K11: Invoice has 1 more — users may have been removed after billing
A12: Power Pages vTrial for Makers | B12: 5 | C12: Likely free / trial | D12: 0 | E12: =IF(B12=0,0,D12/B12) | F12: =D12*Invoice_Input!B10 | G12: =D12+F12 | H12: Free/trial — R0.00 pre-filled (no invoice cost expected) | I12: N/A | J12: N/A | K12: Not on invoice (free/trial)
A13: Exchange Online (Plan 1) | B13: 4 | C13: Likely billable | D13: 268.12 | E13: =IF(B13=0,0,D13/B13) | F13: =D13*Invoice_Input!B10 | G13: =D13+F13 | H13: Pre-filled from Invoice INV-0303 (invoice-only SKU — not in admin export) | I13: 4 | J13: 0 | K13: Match
A14: Dynamics 365 Customer Insights Self-Service | B14: 3 | C14: Likely billable | D14: 0 | E14: =IF(B14=0,0,D14/B14) | F14: =D14*Invoice_Input!B10 | G14: =D14+F14 | H14: Enter the excl-VAT invoice amount for this SKU line item | I14: N/A | J14: N/A | K14: Not on invoice (free/trial)
A15: Power Apps per app plan (1 app or website) | B15: 3 | C15: Likely billable | D15: 251.37 | E15: =IF(B15=0,0,D15/B15) | F15: =D15*Invoice_Input!B10 | G15: =D15+F15 | H15: Pre-filled from Invoice INV-0303 (invoice-only SKU — not in admin export) | I15: 3 | J15: -3 | K15: Invoice has 3 more — users may have been removed after billing
A16: Power Automate per user plan | B16: 1 | C16: Likely billable | D16: 251.37 | E16: =IF(B16=0,0,D16/B16) | F16: =D16*Invoice_Input!B10 | G16: =D16+F16 | H16: Pre-filled from Invoice INV-0303 (invoice-only SKU — not in admin export) | I16: 1 | J16: 0 | K16: Match
A17: TOTAL | B17: =SUM(B2:B16) | D17: =SUM(D2:D16) | F17: =SUM(F2:F16) | G17: =SUM(G2:G16) | I17: 280
A19: RECONCILIATION CHECK | C19: Invoice excl VAT | D19: =Invoice_Input!B11
C20: SKU Total excl VAT | D20: =D17
C21: Variance | D21: =D19-D20
C22: Status | D22: =IF(ABS(D21)<0.01,"PASS - Reconciled","FAIL - Check SKU amounts")
A25: QUANTITY DISCREPANCY: Invoice vs Admin Export
A26: SKUs where the invoice quantity differs from the Admin Centre user count. Investigate and rectify before finalising allocation.
A27: SKU | B27: Admin Users | C27: Invoice Qty | D27: Variance | E27: Impact | F27: Action Required
A28: Microsoft 365 Business Standard | B28: 100 | C28: 97 | D28: 3 | E28: Admin has 3 more user(s) — cost per user is lower than invoiced unit price | F28: Check if user(s) were added after the invoice billing date (25/03/2026)
A29: Microsoft 365 Business Premium | B29: 21 | C29: 23 | D29: -2 | E29: Invoice bills 2 more user(s) — paying for user(s) not in admin export | F29: Check if user(s) were removed after billing — confirm with COITE/Microsoft
A30: Microsoft 365 E3 | B30: 14 | C30: 15 | D30: -1 | E30: Invoice bills 1 more user(s) — paying for user(s) not in admin export | F30: Check if user(s) were removed after billing — confirm with COITE/Microsoft
A31: Power BI Premium Per User | B31: 6 | C31: 7 | D31: -1 | E31: Invoice bills 1 more user(s) — paying for user(s) not in admin export | F31: Check if user(s) were removed after billing — confirm with COITE/Microsoft
A32: Power Apps per app plan (1 app or website) | B32: 0 | C32: 3 | D32: -3 | E32: Invoice bills 3 more user(s) — paying for user(s) not in admin export | F32: Check if user(s) were removed after billing — confirm with COITE/Microsoft

Sheet Allocation_Detail
A1: Licensed Email | B1: Licensed Display Name | C1: Division | D1: Employee Number | E1: Match Status | F1: Review Required | G1: SKU | H1: Billing Hint | I1: Monthly Invoice Amount | J1: Active Users on SKU | K1: Unit Cost | L1: Allocated Cost | M1: Mapping Note | N1: Optimisation Flag
A2: admin@WearCheckRS.com | B2: Admin | C2: RS | E2: Mapped by rule | F2: No | G2: Microsoft Defender for Office 365 (Plan 2) | H2: Likely billable | I2: =IFERROR(VLOOKUP(G2,SKU_Cost_Input!$A$2:$E$16,4,FALSE),0) | J2: =IFERROR(VLOOKUP(G2,SKU_Cost_Input!$A$2:$E$16,2,FALSE),0) | K2: =IF(J2=0,0,I2/J2) | L2: =K2 | M2: Generic/shared/service account defaulted to RS per instruction
A3: admin@WearCheckRS.com | B3: Admin | C3: RS | E3: Mapped by rule | F3: No | G3: Microsoft Fabric (Free) | H3: Likely free / trial | I3: =IFERROR(VLOOKUP(G3,SKU_Cost_Input!$A$2:$E$16,4,FALSE),0) | J3: =IFERROR(VLOOKUP(G3,SKU_Cost_Input!$A$2:$E$16,2,FALSE),0) | K3: =IF(J3=0,0,I3/J3) | L3: =K3 | M3: Generic/shared/service account defaulted to RS per instruction
A4: admin@WearCheckRS.com | B4: Admin | C4: RS | E4: Mapped by rule | F4: No | G4: Microsoft 365 E3 | H4: Likely billable | I4: =IFERROR(VLOOKUP(G4,SKU_Cost_Input!$A$2:$E$16,4,FALSE),0) | J4: =IFERROR(VLOOKUP(G4,SKU_Cost_Input!$A$2:$E$16,2,FALSE),0) | K4: =IF(J4=0,0,I4/J4) | L4: =K4 | M4: Generic/shared/service account defaulted to RS per instruction | N4: Review: E3 may be downgradeable to E1 or Business Basic
A5: A.Ludick@WearCheckRS.com | B5: Adri Ludick | C5: RS | D5: WC492 | E5: Matched | F5: No | G5: Microsoft 365 Business Premium | H5: Likely billable | I5: =IFERROR(VLOOKUP(G5,SKU_Cost_Input!$A$2:$E$16,4,FALSE),0) | J5: =IFERROR(VLOOKUP(G5,SKU_Cost_Input!$A$2:$E$16,2,FALSE),0) | K5: =IF(J5=0,0,I5/J5) | L5: =K5 | M5: Exact company email match | N5: Review: Business Premium — consider Business Basic/Standard
A6: A.Ludick@WearCheckRS.com | B6: Adri Ludick | C6: RS | D6: WC492 | E6: Matched | F6: No | G6: Microsoft Copilot Studio Viral Trial | H6: Likely free / trial | I6: =IFERROR(VLOOKUP(G6,SKU_Cost_Input!$A$2:$E$16,4,FALSE),0) | J6: =IFERROR(VLOOKUP(G6,SKU_Cost_Input!$A$2:$E$16,2,FALSE),0) | K6: =IF(J6=0,0,I6/J6) | L6: =K6 | M6: Exact company email match
A7: A.Ludick@WearCheckRS.com | B7: Adri Ludick | C7: RS | D7: WC492 | E7: Matched | F7: No | G7: Microsoft Defender for Office 365 (Plan 2) | H7: Likely billable | I7: =IFERROR(VLOOKUP(G7,SKU_Cost_Input!$A$2:$E$16,4,FALSE),0) | J7: =IFERROR(VLOOKUP(G7,SKU_Cost_Input!$A$2:$E$16,2,FALSE),0) | K7: =IF(J7=0,0,I7/J7) | L7: =K7 | M7: Exact company email match
A8: A.Ludick@WearCheckRS.com | B8: Adri Ludick | C8: RS | D8: WC492 | E8: Matched | F8: No | G8: Microsoft Power Automate Free | H8: Likely free / trial | I8: =IFERROR(VLOOKUP(G8,SKU_Cost_Input!$A$2:$E$16,4,FALSE),0) | J8: =IFERROR(VLOOKUP(G8,SKU_Cost_Input!$A$2:$E$16,2,FALSE),0) | K8: =IF(J8=0,0,I8/J8) | L8: =K8 | M8: Exact company email match
A9: Adri.ludick@WearCheckRS.com | B9: Adri Ludick Old | C9: RS | E9: Ex-Employee | F9: No | G9: Microsoft Defender for Office 365 (Plan 2) | H9: Likely billable | I9: =IFERROR(VLOOKUP(G9,SKU_Cost_Input!$A$2:$E$16,4,FALSE),0) | J9: =IFERROR(VLOOKUP(G9,SKU_Cost_Input!$A$2:$E$16,2,FALSE),0) | K9: =IF(J9=0,0,I9/J9) | L9: =K9 | M9: Old account — new email A.Ludick@WearCheckRS.com is active. FLAG: Remove this licence.
A10: Adri.ludick@WearCheckRS.com | B10: Adri Ludick Old | C10: RS | E10: Ex-Employee | F10: No | G10: Microsoft Power Automate Free | H10: Likely free / trial | I10: =IFERROR(VLOOKUP(G10,SKU_Cost_Input!$A$2:$E$16,4,FALSE),0) | J10: =IFERROR(VLOOKUP(G10,SKU_Cost_Input!$A$2:$E$16,2,FALSE),0) | K10: =IF(J10=0,0,I10/J10) | L10: =K10 | M10: Old account — new email A.Ludick@WearCheckRS.com is active. FLAG: Remove this licence.
A11: Adri.ludick@WearCheckRS.com | B11: Adri Ludick Old | C11: RS | E11: Ex-Employee | F11: No | G11: Microsoft 365 Business Standard | H11: Likely billable | I11: =IFERROR(VLOOKUP(G11,SKU_Cost_Input!$A$2:$E$16,4,FALSE),0) | J11: =IFERROR(VLOOKUP(G11,SKU_Cost_Input!$A$2:$E$16,2,FALSE),0) | K11: =IF(J11=0,0,I11/J11) | L11: =K11 | M11: Old account — new email A.Ludick@WearCheckRS.com is active. FLAG: Remove this licence. | N11: Review: Business Standard — consider Business Basic if sufficient
A12: adriaanb@WearCheckRS.com | B12: Adriaan Bouwer | C12: RS | D12: WC383 | E12: Matched | F12: No | G12: Microsoft Defender for Office 365 (Plan 2) | H12: Likely billable | I12: =IFERROR(VLOOKUP(G12,SKU_Cost_Input!$A$2:$E$16,4,FALSE),0) | J12: =IFERROR(VLOOKUP(G12,SKU_Cost_Input!$A$2:$E$16,2,FALSE),0) | K12: =IF(J12=0,0,I12/J12) | L12: =K12 | M12: Exact company email match
A13: adriaanb@WearCheckRS.com | B13: Adriaan Bouwer | C13: RS | D13: WC383 | E13: Matched | F13: No | G13: Microsoft Power Automate Free | H13: Likely free / trial | I13: =IFERROR(VLOOKUP(G13,SKU_Cost_Input!$A$2:$E$16,4,FALSE),0) | J13: =IFERROR(VLOOKUP(G13,SKU_Cost_Input!$A$2:$E$16,2,FALSE),0) | K13: =IF(J13=0,0,I13/J13) | L13: =K13 | M13: Exact company email match
A14: adriaanb@WearCheckRS.com | B14: Adriaan Bouwer | C14: RS | D14: WC383 | E14: Matched | F14: No | G14: Microsoft 365 Business Standard | H14: Likely billable | I14: =IFERROR(VLOOKUP(G14,SKU_Cost_Input!$A$2:$E$16,4,FALSE),0) | J14: =IFERROR(VLOOKUP(G14,SKU_Cost_Input!$A$2:$E$16,2,FALSE),0) | K14: =IF(J14=0,0,I14/J14) | L14: =K14 | M14: Exact company email match | N14: Review: Business Standard — consider Business Basic if sufficient
A15: adriaanb@WearCheckRS.com | B15: Adriaan Bouwer | C15: RS | D15: WC383 | E15: Matched | F15: No | G15: Microsoft Fabric (Free) | H15: Likely free / trial | I15: =IFERROR(VLOOKUP(G15,SKU_Cost_Input!$A$2:$E$16,4,FALSE),0) | J15: =IFERROR(VLOOKUP(G15,SKU_Cost_Input!$A$2:$E$16,2,FALSE),0) | K15: =IF(J15=0,0,I15/J15) | L15: =K15 | M15: Exact company email match
A16: afs_app@WearCheckRS.com | B16: AFS Application | C16: AFS | E16: Mapped by rule | F16: No | G16: Microsoft Power Automate Free | H16: Likely free / trial | I16: =IFERROR(VLOOKUP(G16,SKU_Cost_Input!$A$2:$E$16,4,FALSE),0) | J16: =IFERROR(VLOOKUP(G16,SKU_Cost_Input!$A$2:$E$16,2,FALSE),0) | K16: =IF(J16=0,0,I16/J16) | L16: =K16 | M16: Generic/shared/service account defaulted to RS per instruction
A17: afs_app@WearCheckRS.com | B17: AFS Application | C17: AFS | E17: Mapped by rule | F17: No | G17: Exchange Online (Plan 1) | H17: Likely billable | I17: =IFERROR(VLOOKUP(G17,SKU_Cost_Input!$A$2:$E$16,4,FALSE),0) | J17: =IFERROR(VLOOKUP(G17,SKU_Cost_Input!$A$2:$E$16,2,FALSE),0) | K17: =IF(J17=0,0,I17/J17) | L17: =K17 | M17: Generic/shared/service account defaulted to RS per instruction
A18: Alex@WearCheckRS.com | B18: Alex Outram | C18: RS | D18: WEC105 | E18: Matched | F18: No | G18: Microsoft Defender for Office 365 (Plan 2) | H18: Likely billable | I18: =IFERROR(VLOOKUP(G18,SKU_Cost_Input!$A$2:$E$16,4,FALSE),0) | J18: =IFERROR(VLOOKUP(G18,SKU_Cost_Input!$A$2:$E$16,2,FALSE),0) | K18: =IF(J18=0,0,I18/J18) | L18: =K18 | M18: Exact company email match
A19: Alex@WearCheckRS.com | B19: Alex Outram | C19: RS | D19: WEC105 | E19: Matched | F19: No | G19: Microsoft Power Automate Free | H19: Likely free / trial | I19: =IFERROR(VLOOKUP(G19,SKU_Cost_Input!$A$2:$E$16,4,FALSE),0) | J19: =IFERROR(VLOOKUP(G19,SKU_Cost_Input!$A$2:$E$16,2,FALSE),0) | K19: =IF(J19=0,0,I19/J19) | L19: =K19 | M19: Exact company email match
A20: Alex@WearCheckRS.com | B20: Alex Outram | C20: RS | D20: WEC105 | E20: Matched | F20: No | G20: Microsoft Fabric (Free) | H20: Likely free / trial | I20: =IFERROR(VLOOKUP(G20,SKU_Cost_Input!$A$2:$E$16,4,FALSE),0) | J20: =IFERROR(VLOOKUP(G20,SKU_Cost_Input!$A$2:$E$16,2,FALSE),0) | K20: =IF(J20=0,0,I20/J20) | L20: =K20 | M20: Exact company email match
A21: Alex@WearCheckRS.com | B21: Alex Outram | C21: RS | D21: WEC105 | E21: Matched | F21: No | G21: Microsoft 365 Business Standard | H21: Likely billable | I21: =IFERROR(VLOOKUP(G21,SKU_Cost_Input!$A$2:$E$16,4,FALSE),0) | J21: =IFERROR(VLOOKUP(G21,SKU_Cost_Input!$A$2:$E$16,2,FALSE),0) | K21: =IF(J21=0,0,I21/J21) | L21: =K21 | M21: Exact company email match | N21: Review: Business Standard — consider Business Basic if sufficient
A22: Allan@WearCheckRS.com | B22: Allan Stuurman | C22: RS | D22: WEC123 | E22: Matched | F22: No | G22: Microsoft Defender for Office 365 (Plan 2) | H22: Likely billable | I22: =IFERROR(VLOOKUP(G22,SKU_Cost_Input!$A$2:$E$16,4,FALSE),0) | J22: =IFERROR(VLOOKUP(G22,SKU_Cost_Input!$A$2:$E$16,2,FALSE),0) | K22: =IF(J22=0,0,I22/J22) | L22: =K22 | M22: Exact company email match
A23: Allan@WearCheckRS.com | B23: Allan Stuurman | C23: RS | D23: WEC123 | E23: Matched | F23: No | G23: Microsoft 365 Business Standard | H23: Likely billable | I23: =IFERROR(VLOOKUP(G23,SKU_Cost_Input!$A$2:$E$16,4,FALSE),0) | J23: =IFERROR(VLOOKUP(G23,SKU_Cost_Input!$A$2:$E$16,2,FALSE),0) | K23: =IF(J23=0,0,I23/J23) | L23: =K23 | M23: Exact company email match | N23: Review: Business Standard — consider Business Basic if sufficient
A24: Andrew@wearcheckrs.com | B24: Andrew Robb | C24: RS | D24: WEC103 | E24: Matched | F24: No | G24: Microsoft 365 Business Premium | H24: Likely billable | I24: =IFERROR(VLOOKUP(G24,SKU_Cost_Input!$A$2:$E$16,4,FALSE),0) | J24: =IFERROR(VLOOKUP(G24,SKU_Cost_Input!$A$2:$E$16,2,FALSE),0) | K24: =IF(J24=0,0,I24/J24) | L24: =K24 | M24: Exact company email match | N24: Review: Business Premium — consider Business Basic/Standard
A25: Andrew@wearcheckrs.com | B25: Andrew Robb | C25: RS | D25: WEC103 | E25: Matched | F25: No | G25: Microsoft Defender for Office 365 (Plan 2) | H25: Likely billable | I25: =IFERROR(VLOOKUP(G25,SKU_Cost_Input!$A$2:$E$16,4,FALSE),0) | J25: =IFERROR(VLOOKUP(G25,SKU_Cost_Input!$A$2:$E$16,2,FALSE),0) | K25: =IF(J25=0,0,I25/J25) | L25: =K25 | M25: Exact company email match
A26: Andrew@wearcheckrs.com | B26: Andrew Robb | C26: RS | D26: WEC103 | E26: Matched | F26: No | G26: Microsoft Fabric (Free) | H26: Likely free / trial | I26: =IFERROR(VLOOKUP(G26,SKU_Cost_Input!$A$2:$E$16,4,FALSE),0) | J26: =IFERROR(VLOOKUP(G26,SKU_Cost_Input!$A$2:$E$16,2,FALSE),0) | K26: =IF(J26=0,0,I26/J26) | L26: =K26 | M26: Exact company email match
A27: annahm@WearCheckRS.com | B27: Annah Modutwane | C27: RS | D27: WC484 | E27: Matched | F27: No | G27: Microsoft Defender for Office 365 (Plan 2) | H27: Likely billable | I27: =IFERROR(VLOOKUP(G27,SKU_Cost_Input!$A$2:$E$16,4,FALSE),0) | J27: =IFERROR(VLOOKUP(G27,SKU_Cost_Input!$A$2:$E$16,2,FALSE),0) | K27: =IF(J27=0,0,I27/J27) | L27: =K27 | M27: Exact company email match
A28: annahm@WearCheckRS.com | B28: Annah Modutwane | C28: RS | D28: WC484 | E28: Matched | F28: No | G28: Microsoft Power Automate Free | H28: Likely free / trial | I28: =IFERROR(VLOOKUP(G28,SKU_Cost_Input!$A$2:$E$16,4,FALSE),0) | J28: =IFERROR(VLOOKUP(G28,SKU_Cost_Input!$A$2:$E$16,2,FALSE),0) | K28: =IF(J28=0,0,I28/J28) | L28: =K28 | M28: Exact company email match
A29: annahm@WearCheckRS.com | B29: Annah Modutwane | C29: RS | D29: WC484 | E29: Matched | F29: No | G29: Microsoft Fabric (Free) | H29: Likely free / trial | I29: =IFERROR(VLOOKUP(G29,SKU_Cost_Input!$A$2:$E$16,4,FALSE),0) | J29: =IFERROR(VLOOKUP(G29,SKU_Cost_Input!$A$2:$E$16,2,FALSE),0) | K29: =IF(J29=0,0,I29/J29) | L29: =K29 | M29: Exact company email match
A30: annahm@WearCheckRS.com | B30: Annah Modutwane | C30: RS | D30: WC484 | E30: Matched | F30: No | G30: Microsoft 365 Business Standard | H30: Likely billable | I30: =IFERROR(VLOOKUP(G30,SKU_Cost_Input!$A$2:$E$16,4,FALSE),0) | J30: =IFERROR(VLOOKUP(G30,SKU_Cost_Input!$A$2:$E$16,2,FALSE),0) | K30: =IF(J30=0,0,I30/J30) | L30: =K30 | M30: Exact company email match | N30: Review: Business Standard — consider Business Basic if sufficient
A31: annemie@WearCheckRS.com | B31: Annemie Willer | C31: RS | D31: WC319 | E31: Matched | F31: No | G31: Microsoft Defender for Office 365 (Plan 2) | H31: Likely billable | I31: =IFERROR(VLOOKUP(G31,SKU_Cost_Input!$A$2:$E$16,4,FALSE),0) | J31: =IFERROR(VLOOKUP(G31,SKU_Cost_Input!$A$2:$E$16,2,FALSE),0) | K31: =IF(J31=0,0,I31/J31) | L31: =K31 | M31: Exact company email match
A32: annemie@WearCheckRS.com | B32: Annemie Willer | C32: RS | D32: WC319 | E32: Matched | F32: No | G32: Power BI Premium Per User | H32: Likely billable | I32: =IFERROR(VLOOKUP(G32,SKU_Cost_Input!$A$2:$E$16,4,FALSE),0) | J32: =IFERROR(VLOOKUP(G32,SKU_Cost_Input!$A$2:$E$16,2,FALSE),0) | K32: =IF(J32=0,0,I32/J32) | L32: =K32 | M32: Exact company email match
A33: annemie@WearCheckRS.com | B33: Annemie Willer | C33: RS | D33: WC319 | E33: Matched | F33: No | G33: Microsoft Copilot Studio Viral Trial | H33: Likely free / trial | I33: =IFERROR(VLOOKUP(G33,SKU_Cost_Input!$A$2:$E$16,4,FALSE),0) | J33: =IFERROR(VLOOKUP(G33,SKU_Cost_Input!$A$2:$E$16,2,FALSE),0) | K33: =IF(J33=0,0,I33/J33) | L33: =K33 | M33: Exact company email match
A34: annemie@WearCheckRS.com | B34: Annemie Willer | C34: RS | D34: WC319 | E34: Matched | F34: No | G34: Microsoft Power Apps Plan 2 Trial | H34: Likely free / trial | I34: =IFERROR(VLOOKUP(G34,SKU_Cost_Input!$A$2:$E$16,4,FALSE),0) | J34: =IFERROR(VLOOKUP(G34,SKU_Cost_Input!$A$2:$E$16,2,FALSE),0) | K34: =IF(J34=0,0,I34/J34) | L34: =K34 | M34: Exact company email match
A35: annemie@WearCheckRS.com | B35: Annemie Willer | C35: RS | D35: WC319 | E35: Matched | F35: No | G35: Microsoft 365 E3 | H35: Likely billable | I35: =IFERROR(VLOOKUP(G35,SKU_Cost_Input!$A$2:$E$16,4,FALSE),0) | J35: =IFERROR(VLOOKUP(G35,SKU_Cost_Input!$A$2:$E$16,2,FALSE),0) | K35: =IF(J35=0,0,I35/J35) | L35: =K35 | M35: Exact company email match | N35: Review: E3 may be downgradeable to E1 or Business Basic
A36: annemie@WearCheckRS.com | B36: Annemie Willer | C36: RS | D36: WC319 | E36: Matched | F36: No | G36: Microsoft Fabric (Free) | H36: Likely free / trial | I36: =IFERROR(VLOOKUP(G36,SKU_Cost_Input!$A$2:$E$16,4,FALSE),0) | J36: =IFERROR(VLOOKUP(G36,SKU_Cost_Input!$A$2:$E$16,2,FALSE),0) | K36: =IF(J36=0,0,I36/J36) | L36: =K36 | M36: Exact company email match
A37: annemie@WearCheckRS.com | B37: Annemie Willer | C37: RS | D37: WC319 | E37: Matched | F37: No | G37: Microsoft Power Automate Free | H37: Likely free / trial | I37: =IFERROR(VLOOKUP(G37,SKU_Cost_Input!$A$2:$E$16,4,FALSE),0) | J37: =IFERROR(VLOOKUP(G37,SKU_Cost_Input!$A$2:$E$16,2,FALSE),0) | K37: =IF(J37=0,0,I37/J37) | L37: =K37 | M37: Exact company email match
A38: Antonio.Ehrke@WearCheckRS.com | B38: Antonio Ehrke | C38: AFS | D38: WC503 | E38: Matched | F38: No | G38: Microsoft Defender for Office 365 (Plan 2) | H38: Likely billable | I38: =IFERROR(VLOOKUP(G38,SKU_Cost_Input!$A$2:$E$16,4,FALSE),0) | J38: =IFERROR(VLOOKUP(G38,SKU_Cost_Input!$A$2:$E$16,2,FALSE),0) | K38: =IF(J38=0,0,I38/J38) | L38: =K38 | M38: Exact company email match
A39: Antonio.Ehrke@WearCheckRS.com | B39: Antonio Ehrke | C39: AFS | D39: WC503 | E39: Matched | F39: No | G39: Microsoft 365 Business Standard | H39: Likely billable | I39: =IFERROR(VLOOKUP(G39,SKU_Cost_Input!$A$2:$E$16,4,FALSE),0) | J39: =IFERROR(VLOOKUP(G39,SKU_Cost_Input!$A$2:$E$16,2,FALSE),0) | K39: =IF(J39=0,0,I39/J39) | L39: =K39 | M39: Exact company email match | N39: Review: Business Standard — consider Business Basic if sufficient
A40: Armindo@WearCheckRS.com | B40: Armindo Mucacho | C40: Mozambique | D40: Unknown | E40: Matched | F40: No | G40: Microsoft Defender for Office 365 (Plan 2) | H40: Likely billable | I40: =IFERROR(VLOOKUP(G40,SKU_Cost_Input!$A$2:$E$16,4,FALSE),0) | J40: =IFERROR(VLOOKUP(G40,SKU_Cost_Input!$A$2:$E$16,2,FALSE),0) | K40: =IF(J40=0,0,I40/J40) | L40: =K40 | M40: Exact company email match
...

Sheet Allocation_Pivot
A1: Clean Allocation Table: Division x SKU
A2: Cost values update automatically from SKU_Cost_Input
A4: Division | B4: SKU | C4: Users | D4: Allocated Cost
A5: RS | B5: Microsoft Defender for Office 365 (Plan 2) | C5: =COUNTIFS(Allocation_Detail!$C$2:$C$406,A5,Allocation_Detail!$G$2:$G$406,B5) | D5: =SUMIFS(Allocation_Detail!$L$2:$L$406,Allocation_Detail!$C$2:$C$406,A5,Allocation_Detail!$G$2:$G$406,B5)
A6: RS | B6: Microsoft 365 Business Standard | C6: =COUNTIFS(Allocation_Detail!$C$2:$C$406,A6,Allocation_Detail!$G$2:$G$406,B6) | D6: =SUMIFS(Allocation_Detail!$L$2:$L$406,Allocation_Detail!$C$2:$C$406,A6,Allocation_Detail!$G$2:$G$406,B6)
A7: RS | B7: Microsoft Power Automate Free | C7: =COUNTIFS(Allocation_Detail!$C$2:$C$406,A7,Allocation_Detail!$G$2:$G$406,B7) | D7: =SUMIFS(Allocation_Detail!$L$2:$L$406,Allocation_Detail!$C$2:$C$406,A7,Allocation_Detail!$G$2:$G$406,B7)
A8: RS | B8: Microsoft Fabric (Free) | C8: =COUNTIFS(Allocation_Detail!$C$2:$C$406,A8,Allocation_Detail!$G$2:$G$406,B8) | D8: =SUMIFS(Allocation_Detail!$L$2:$L$406,Allocation_Detail!$C$2:$C$406,A8,Allocation_Detail!$G$2:$G$406,B8)
A9: RS | B9: Microsoft 365 Business Premium | C9: =COUNTIFS(Allocation_Detail!$C$2:$C$406,A9,Allocation_Detail!$G$2:$G$406,B9) | D9: =SUMIFS(Allocation_Detail!$L$2:$L$406,Allocation_Detail!$C$2:$C$406,A9,Allocation_Detail!$G$2:$G$406,B9)
A10: RS | B10: Microsoft 365 E3 | C10: =COUNTIFS(Allocation_Detail!$C$2:$C$406,A10,Allocation_Detail!$G$2:$G$406,B10) | D10: =SUMIFS(Allocation_Detail!$L$2:$L$406,Allocation_Detail!$C$2:$C$406,A10,Allocation_Detail!$G$2:$G$406,B10)
A11: RS | B11: Microsoft Copilot Studio Viral Trial | C11: =COUNTIFS(Allocation_Detail!$C$2:$C$406,A11,Allocation_Detail!$G$2:$G$406,B11) | D11: =SUMIFS(Allocation_Detail!$L$2:$L$406,Allocation_Detail!$C$2:$C$406,A11,Allocation_Detail!$G$2:$G$406,B11)
A12: RS | B12: Microsoft Power Apps Plan 2 Trial | C12: =COUNTIFS(Allocation_Detail!$C$2:$C$406,A12,Allocation_Detail!$G$2:$G$406,B12) | D12: =SUMIFS(Allocation_Detail!$L$2:$L$406,Allocation_Detail!$C$2:$C$406,A12,Allocation_Detail!$G$2:$G$406,B12)
A13: RS | B13: Microsoft Power Apps for Developer | C13: =COUNTIFS(Allocation_Detail!$C$2:$C$406,A13,Allocation_Detail!$G$2:$G$406,B13) | D13: =SUMIFS(Allocation_Detail!$L$2:$L$406,Allocation_Detail!$C$2:$C$406,A13,Allocation_Detail!$G$2:$G$406,B13)
A14: RS | B14: Power BI Premium Per User | C14: =COUNTIFS(Allocation_Detail!$C$2:$C$406,A14,Allocation_Detail!$G$2:$G$406,B14) | D14: =SUMIFS(Allocation_Detail!$L$2:$L$406,Allocation_Detail!$C$2:$C$406,A14,Allocation_Detail!$G$2:$G$406,B14)
A15: RS | B15: Power Pages vTrial for Makers | C15: =COUNTIFS(Allocation_Detail!$C$2:$C$406,A15,Allocation_Detail!$G$2:$G$406,B15) | D15: =SUMIFS(Allocation_Detail!$L$2:$L$406,Allocation_Detail!$C$2:$C$406,A15,Allocation_Detail!$G$2:$G$406,B15)
A16: RS | B16: Exchange Online (Plan 1) | C16: =COUNTIFS(Allocation_Detail!$C$2:$C$406,A16,Allocation_Detail!$G$2:$G$406,B16) | D16: =SUMIFS(Allocation_Detail!$L$2:$L$406,Allocation_Detail!$C$2:$C$406,A16,Allocation_Detail!$G$2:$G$406,B16)
... A64: Mozambique | B64: Power Automate per user plan | C64: =COUNTIFS(Allocation_Detail!$C$2:$C$406,A64,Allocation_Detail!$G$2:$G$406,B64) | D64: =SUMIFS(Allocation_Detail!$L$2:$L$406,Allocation_Detail!$C$2:$C$406,A64,Allocation_Detail!$G$2:$G$406,B64)
A65: TOTAL | C65: =SUM(C5:C64) | D65: =SUM(D5:D64)

Sheet Division_Summary
A1: Microsoft License Allocation Summary
A2: =Invoice_Input!B4
A3: Enter monthly invoice amounts on SKU_Cost_Input. Values update automatically.
A5: KPI | B5: Value
A6: Billing Period | B6: =Invoice_Input!B4
A7: Licensed accounts in export | B7: 147
A8: Matched to cost centre (High) | B8: =COUNTIF(User_Match!$H$2:$H$148,"High")
A9: Accounts needing review | B9: =COUNTIF(User_Match!$I$2:$I$148,"Yes")
A10: Invoice Total (excl VAT) | B10: =Invoice_Input!B11
A11: VAT Amount | B11: =SKU_Cost_Input!F17
A12: Invoice Total (incl VAT) | B12: =Invoice_Input!B9
A13: Allocated Total (excl VAT) | B13: =SKU_Cost_Input!D17
A14: Reconciliation Status | B14: =Invoice_Input!B19
A15: SKU Qty Discrepancies (Invoice vs Admin) | B15: 5
A16: Total Tenant Accounts (CSV) | B16: 842
A17: Licensed Users (CSV) | B17: 147
A18: Unlicensed Accounts | B18: 641
A19: Soft-Deleted Accounts | B19: 54
A20: Unassigned Paid Licences (total) | B20: 7
A21: Wasted Monthly Spend (excl VAT) | B21: 1994.21
A22: COITE Queries Raised | B22: 6
A23: Ex-Employee Licences (remove) | B23: =COUNTIF(User_Match!$J$2:$J$148,"Ex-Employee")
A24: Contractor Licences | B24: =COUNTIF(User_Match!$J$2:$J$148,"Contractor")
A27: Division | B27: Licensed Accounts | C27: Review Accounts | D27: SKU Assignments | E27: Allocated Monthly Cost (excl VAT) | F27: % of Total Cost
A28: RS | B28: =COUNTIF(User_Match!$F$2:$F$148,A28) | C28: =COUNTIFS(User_Match!$F$2:$F$148,A28,User_Match!$I$2:$I$148,"Yes") | D28: =COUNTIF(Allocation_Detail!$C$2:$C$406,A28) | E28: =SUMIF(Allocation_Detail!$C$2:$C$406,A28,Allocation_Detail!$L$2:$L$406) | F28: =IF(E32=0,0,E28/E32)
A29: AFS | B29: =COUNTIF(User_Match!$F$2:$F$148,A29) | C29: =COUNTIFS(User_Match!$F$2:$F$148,A29,User_Match!$I$2:$I$148,"Yes") | D29: =COUNTIF(Allocation_Detail!$C$2:$C$406,A29) | E29: =SUMIF(Allocation_Detail!$C$2:$C$406,A29,Allocation_Detail!$L$2:$L$406) | F29: =IF(E32=0,0,E29/E32)
A30: Namibia | B30: =COUNTIF(User_Match!$F$2:$F$148,A30) | C30: =COUNTIFS(User_Match!$F$2:$F$148,A30,User_Match!$I$2:$I$148,"Yes") | D30: =COUNTIF(Allocation_Detail!$C$2:$C$406,A30) | E30: =SUMIF(Allocation_Detail!$C$2:$C$406,A30,Allocation_Detail!$L$2:$L$406) | F30: =IF(E32=0,0,E30/E32)
A31: Mozambique | B31: =COUNTIF(User_Match!$F$2:$F$148,A31) | C31: =COUNTIFS(User_Match!$F$2:$F$148,A31,User_Match!$I$2:$I$148,"Yes") | D31: =COUNTIF(Allocation_Detail!$C$2:$C$406,A31) | E31: =SUMIF(Allocation_Detail!$C$2:$C$406,A31,Allocation_Detail!$L$2:$L$406) | F31: =IF(E32=0,0,E31/E32)
A32: TOTAL | B32: =SUM(B28:B31) | C32: =SUM(C28:C31) | D32: =SUM(D28:D31) | E32: =SUM(E28:E31) | F32: =IF(E32=0,0,E32/E32)
A35: SKU Cost Breakdown
A36: SKU | B36: Active Users | C36: Invoice Amount (excl VAT) | D36: Unit Cost Per User | E36: VAT Amount | F36: Total incl VAT
A37: Microsoft Defender for Office 365 (Plan 2) | B37: =SKU_Cost_Input!B2 | C37: =SKU_Cost_Input!D2 | D37: =SKU_Cost_Input!E2 | E37: =SKU_Cost_Input!F2 | F37: =SKU_Cost_Input!G2
A38: Microsoft 365 Business Standard | B38: =SKU_Cost_Input!B3 | C38: =SKU_Cost_Input!D3 | D38: =SKU_Cost_Input!E3 | E38: =SKU_Cost_Input!F3 | F38: =SKU_Cost_Input!G3
A39: Microsoft Power Automate Free | B39: =SKU_Cost_Input!B4 | C39: =SKU_Cost_Input!D4 | D39: =SKU_Cost_Input!E4 | E39: =SKU_Cost_Input!F4 | F39: =SKU_Cost_Input!G4
A40: Microsoft Fabric (Free) | B40: =SKU_Cost_Input!B5 | C40: =SKU_Cost_Input!D5 | D40: =SKU_Cost_Input!E5 | E40: =SKU_Cost_Input!F5 | F40: =SKU_Cost_Input!G5
A41: Microsoft 365 Business Premium | B41: =SKU_Cost_Input!B6 | C41: =SKU_Cost_Input!D6 | D41: =SKU_Cost_Input!E6 | E41: =SKU_Cost_Input!F6 | F41: =SKU_Cost_Input!G6
A42: Microsoft 365 E3 | B42: =SKU_Cost_Input!B7 | C42: =SKU_Cost_Input!D7 | D42: =SKU_Cost_Input!E7 | E42: =SKU_Cost_Input!F7 | F42: =SKU_Cost_Input!G7
A43: Microsoft Copilot Studio Viral Trial | B43: =SKU_Cost_Input!B8 | C43: =SKU_Cost_Input!D8 | D43: =SKU_Cost_Input!E8 | E43: =SKU_Cost_Input!F8 | F43: =SKU_Cost_Input!G8
A44: Microsoft Power Apps Plan 2 Trial | B44: =SKU_Cost_Input!B9 | C44: =SKU_Cost_Input!D9 | D44: =SKU_Cost_Input!E9 | E44: =SKU_Cost_Input!F9 | F44: =SKU_Cost_Input!G9
A45: Microsoft Power Apps for Developer | B45: =SKU_Cost_Input!B10 | C45: =SKU_Cost_Input!D10 | D45: =SKU_Cost_Input!E10 | E45: =SKU_Cost_Input!F10 | F45: =SKU_Cost_Input!G10
...

Sheet Licence_Cleanup
A1: Licences Flagged for Removal / Management Review
A2: These users are no longer employees, are contractors, or need management review. Action: remove or reassign licences.
A4: Display Name | B4: Email | C4: User Status | D4: Licences Held | E4: Licence Count | F4: Est. Monthly Cost (excl VAT) | G4: Reason / Note | H4: Action Required
A5: Adri Ludick Old | B5: Adri.ludick@WearCheckRS.com | C5: Ex-Employee | D5: Microsoft Defender for Office 365 (Plan 2)+Microsoft Power Automate Free+Microsoft 365 Business Standard | E5: 3 | F5: =SUMIF(Allocation_Detail!$A$2:$A$406,B5,Allocation_Detail!$L$2:$L$406) | G5: Old account — new email A.Ludick@WearCheckRS.com is active. FLAG: Remove this licence. | H5: REMOVE LICENCE — no longer an employee
A6: Christian Geel | B6: Christian@WearCheckRS.com | C6: Ex-Employee | D6: Microsoft Fabric (Free)+Microsoft Power Automate Free | E6: 2 | F6: =SUMIF(Allocation_Detail!$A$2:$A$406,B6,Allocation_Detail!$L$2:$L$406) | G6: No longer an employee. FLAG: Remove licence. | H6: REMOVE LICENCE — no longer an employee
A7: Gladwin Sekharume | B7: GladwinS@WearCheckRS.com | C7: Ex-Employee | D7: Microsoft Defender for Office 365 (Plan 2)+Microsoft 365 Business Standard | E7: 2 | F7: =SUMIF(Allocation_Detail!$A$2:$A$406,B7,Allocation_Detail!$L$2:$L$406) | G7: No longer an employee. FLAG: Remove licence. | H7: REMOVE LICENCE — no longer an employee
A8: Ivan Langa | B8: Ivan@WearCheckRS.com | C8: Ex-Employee | D8: Microsoft Defender for Office 365 (Plan 2)+Microsoft Fabric (Free)+Microsoft 365 Business Standard | E8: 3 | F8: =SUMIF(Allocation_Detail!$A$2:$A$406,B8,Allocation_Detail!$L$2:$L$406) | G8: No longer an employee. FLAG: Remove licence. | H8: REMOVE LICENCE — no longer an employee
A9: Kenneth Moremi | B9: kenneth@WearCheckRS.com | C9: Ex-Employee | D9: Microsoft Defender for Office 365 (Plan 2)+Microsoft 365 Business Standard | E9: 2 | F9: =SUMIF(Allocation_Detail!$A$2:$A$406,B9,Allocation_Detail!$L$2:$L$406) | G9: No longer an employee. FLAG: Remove licence. | H9: REMOVE LICENCE — no longer an employee
A10: Kevin Jonker | B10: kevinj@WearCheckRS.com | C10: Ex-Employee | D10: Microsoft Fabric (Free)+Microsoft Power Automate Free | E10: 2 | F10: =SUMIF(Allocation_Detail!$A$2:$A$406,B10,Allocation_Detail!$L$2:$L$406) | G10: No longer an employee. FLAG: Remove licence. | H10: REMOVE LICENCE — no longer an employee
A11: Mandiso Muchanga | B11: Mandiso@WearCheckRS.com | C11: Ex-Employee | D11: Microsoft Defender for Office 365 (Plan 2)+Microsoft 365 Business Standard | E11: 2 | F11: =SUMIF(Allocation_Detail!$A$2:$A$406,B11,Allocation_Detail!$L$2:$L$406) | G11: No longer an employee. FLAG: Remove licence. | H11: REMOVE LICENCE — no longer an employee
A12: Martin Prinsloo | B12: martin.prinsloo@WearCheckRS.com | C12: Ex-Employee | D12: Microsoft Fabric (Free) | E12: 1 | F12: =SUMIF(Allocation_Detail!$A$2:$A$406,B12,Allocation_Detail!$L$2:$L$406) | G12: No longer an employee. FLAG: Remove licence. | H12: REMOVE LICENCE — no longer an employee
A13: Peter | B13: Peter@WearCheckRS.com | C13: Ex-Employee | D13: Microsoft 365 Business Standard | E13: 1 | F13: =SUMIF(Allocation_Detail!$A$2:$A$406,B13,Allocation_Detail!$L$2:$L$406) | G13: No longer an employee. FLAG: Remove licence. | H13: REMOVE LICENCE — no longer an employee
A14: Thabang Mathumba | B14: thabang@WearCheckRS.com | C14: Ex-Employee | D14: Microsoft Defender for Office 365 (Plan 2)+Microsoft 365 Business Standard | E14: 2 | F14: =SUMIF(Allocation_Detail!$A$2:$A$406,B14,Allocation_Detail!$L$2:$L$406) | G14: No longer an employee. FLAG: Remove licence. | H14: REMOVE LICENCE — no longer an employee
A15: Tumelo | B15: tumelo.samancor@WearCheckRS.com | C15: Ex-Employee | D15: Microsoft Fabric (Free) | E15: 1 | F15: =SUMIF(Allocation_Detail!$A$2:$A$406,B15,Allocation_Detail!$L$2:$L$406) | G15: No longer an employee. FLAG: Remove licence. | H15: REMOVE LICENCE — no longer an employee
A16: Lea Bodenstein | B16: Lea@WearCheckRS.com | C16: Contractor | D16: Microsoft 365 Business Premium+Microsoft Defender for Office 365 (Plan 2)+Microsoft Fabric (Free) | E16: 3 | F16: =SUMIF(Allocation_Detail!$A$2:$A$406,B16,Allocation_Detail!$L$2:$L$406) | G16: Not an employee — contractor. Licence allocated to RS. | H16: Review: keep licence or remove (contractor)
... A19: Christie | B19: christie.samancor@WearCheckRS.com | C19: Management Review | D19: Microsoft Fabric (Free) | E19: 1 | F19: =SUMIF(Allocation_Detail!$A$2:$A$406,B19,Allocation_Detail!$L$2:$L$406) | G19: Not an employee — has free Fabric licence only. Flagged for management review. | H19: Escalate to management for decision
A21: Summary
