Workbook

Sheet Read Me
A1: Microsoft License Allocation Workbook - March 2026
A2: Purpose
A3: Allocate Microsoft license invoice costs by cost centre using SKU-level allocation (Option B).
A4: How to use
A5: 1. Update the Monthly Invoice Amount column on SKU_Cost_Input from the monthly Microsoft invoice.
A6: 2. Review Review_Queue and resolve any low-confidence or unassigned accounts.
A7: 3. Division_Summary will update automatically once invoice amounts are entered.
A8: 4. Keep a month-end copy of the file for audit trail and future trend charts.
A9: Assumptions used in this build
A10: - Shared/generic/service accounts are defaulted to RS, per your instruction.
A11: - Namibia and Mozambique are treated as separate cost centres.
A12: - AFS is taken from Employee Master Department 2 = AFS unless Site says Namibia/Mozambique.
... A17: Accounts needing review: 23

Sheet Division_Summary
A1: Microsoft License Allocation Summary
A2: Enter monthly invoice amounts on SKU_Cost_Input. Cost values here will update automatically.
A4: KPI | B4: Value
A5: Licensed accounts in export | B5: 147
A6: Mapped to a cost centre | B6: =COUNTIF(User_Match!$F$2:$F$148,"<>Unassigned - Review") -> 129
A7: Accounts needing review | B7: =COUNTIF(User_Match!$L$2:$L$148,"Yes") -> 23
A10: Division | B10: Licensed Accounts | C10: Review Accounts | D10: SKU Assignments | E10: Allocated Monthly Cost | F10: % of Allocated Cost
A11: RS | B11: =COUNTIF(User_Match!$F$2:$F$148,A11) -> 94 | C11: =COUNTIFS(User_Match!$F$2:$F$148,A11,User_Match!$L$2:$L$148,"Yes") -> 0 | D11: =COUNTIF(Allocation_Detail!$C$2:$C$406,A11) -> 271 | E11: =SUMIF(Allocation_Detail!$C$2:$C$406,A11,Allocation_Detail!$L$2:$L$406) -> 0 | F11: =IF($E$16=0,0,E11/$E$16) -> 0
A12: AFS | B12: =COUNTIF(User_Match!$F$2:$F$148,A12) -> 25 | C12: =COUNTIFS(User_Match!$F$2:$F$148,A12,User_Match!$L$2:$L$148,"Yes") -> 5 | D12: =COUNTIF(Allocation_Detail!$C$2:$C$406,A12) -> 67 | E12: =SUMIF(Allocation_Detail!$C$2:$C$406,A12,Allocation_Detail!$L$2:$L$406) -> 0 | F12: =IF($E$16=0,0,E12/$E$16) -> 0
A13: Namibia | B13: =COUNTIF(User_Match!$F$2:$F$148,A13) -> 4 | C13: =COUNTIFS(User_Match!$F$2:$F$148,A13,User_Match!$L$2:$L$148,"Yes") -> 0 | D13: =COUNTIF(Allocation_Detail!$C$2:$C$406,A13) -> 10 | E13: =SUMIF(Allocation_Detail!$C$2:$C$406,A13,Allocation_Detail!$L$2:$L$406) -> 0 | F13: =IF($E$16=0,0,E13/$E$16) -> 0
A14: Mozambique | B14: =COUNTIF(User_Match!$F$2:$F$148,A14) -> 6 | C14: =COUNTIFS(User_Match!$F$2:$F$148,A14,User_Match!$L$2:$L$148,"Yes") -> 0 | D14: =COUNTIF(Allocation_Detail!$C$2:$C$406,A14) -> 17 | E14: =SUMIF(Allocation_Detail!$C$2:$C$406,A14,Allocation_Detail!$L$2:$L$406) -> 0 | F14: =IF($E$16=0,0,E14/$E$16) -> 0
A15: Unassigned - Review | B15: =COUNTIF(User_Match!$F$2:$F$148,A15) -> 18 | C15: =COUNTIFS(User_Match!$F$2:$F$148,A15,User_Match!$L$2:$L$148,"Yes") -> 18 | D15: =COUNTIF(Allocation_Detail!$C$2:$C$406,A15) -> 40 | E15: =SUMIF(Allocation_Detail!$C$2:$C$406,A15,Allocation_Detail!$L$2:$L$406) -> 0 | F15: =IF($E$16=0,0,E15/$E$16) -> 0
A16: Total | B16: =SUM(B11:B15) -> 147 | C16: =SUM(C11:C15) -> 23 | D16: =SUM(D11:D15) -> 405 | E16: =SUM(E11:E15) -> 0 | F16: =IF($E$16=0,0,E16/$E$16) -> 0
A19: Top SKU | B19: Users | C19: Invoice Amount | D19: Unit Cost
A20: Microsoft Defender for Office 365 (Plan 2) | B20: 130 | C20: =SKU_Cost_Input!D2 -> 0 | D20: =SKU_Cost_Input!E2 -> 0
A21: Microsoft 365 Business Standard | B21: 100 | C21: =SKU_Cost_Input!D3 -> 0 | D21: =SKU_Cost_Input!E3 -> 0
A22: Microsoft Power Automate Free | B22: 52 | C22: =SKU_Cost_Input!D4 -> 0 | D22: =SKU_Cost_Input!E4 -> 0
A23: Microsoft Fabric (Free) | B23: 50 | C23: =SKU_Cost_Input!D5 -> 0 | D23: =SKU_Cost_Input!E5 -> 0
A24: Microsoft 365 Business Premium | B24: 21 | C24: =SKU_Cost_Input!D6 -> 0 | D24: =SKU_Cost_Input!E6 -> 0
A25: Microsoft 365 E3 | B25: 14 | C25: =SKU_Cost_Input!D7 -> 0 | D25: =SKU_Cost_Input!E7 -> 0
H35: Division | I35: Allocated Monthly Cost
H36: RS | I36: =E11 -> 0
H37: AFS | I37: =E12 -> 0
H38: Namibia | I38: =E13 -> 0
H39: Mozambique | I39: =E14 -> 0
H40: Unassigned - Review | I40: =E15 -> 0

Sheet SKU_Cost_Input
A1: SKU | B1: Active Users | C1: Billing Hint | D1: Monthly Invoice Amount (input) | E1: Unit Cost | F1: Notes
A2: Microsoft Defender for Office 365 (Plan 2) | B2: 130 | C2: Review invoice | D2: 0 | E2: =IF(B2=0,0,D2/B2) -> 0 | F2: Enter the monthly invoice amount for this SKU if it appears on the invoice
A3: Microsoft 365 Business Standard | B3: 100 | C3: Likely billable | D3: 0 | E3: =IF(B3=0,0,D3/B3) -> 0 | F3: Enter the monthly invoice amount for this SKU if it appears on the invoice
A4: Microsoft Power Automate Free | B4: 52 | C4: Likely free / trial | D4: 0 | E4: =IF(B4=0,0,D4/B4) -> 0 | F4: Enter the monthly invoice amount for this SKU if it appears on the invoice
A5: Microsoft Fabric (Free) | B5: 50 | C5: Likely free / trial | D5: 0 | E5: =IF(B5=0,0,D5/B5) -> 0 | F5: Enter the monthly invoice amount for this SKU if it appears on the invoice
A6: Microsoft 365 Business Premium | B6: 21 | C6: Likely billable | D6: 0 | E6: =IF(B6=0,0,D6/B6) -> 0 | F6: Enter the monthly invoice amount for this SKU if it appears on the invoice
A7: Microsoft 365 E3 | B7: 14 | C7: Likely billable | D7: 0 | E7: =IF(B7=0,0,D7/B7) -> 0 | F7: Enter the monthly invoice amount for this SKU if it appears on the invoice
A8: Microsoft Copilot Studio Viral Trial | B8: 7 | C8: Likely free / trial | D8: 0 | E8: =IF(B8=0,0,D8/B8) -> 0 | F8: Enter the monthly invoice amount for this SKU if it appears on the invoice
A9: Microsoft Power Apps Plan 2 Trial | B9: 6 | C9: Likely free / trial | D9: 0 | E9: =IF(B9=0,0,D9/B9) -> 0 | F9: Enter the monthly invoice amount for this SKU if it appears on the invoice
A10: Microsoft Power Apps for Developer | B10: 6 | C10: Review invoice | D10: 0 | E10: =IF(B10=0,0,D10/B10) -> 0 | F10: Enter the monthly invoice amount for this SKU if it appears on the invoice
A11: Power BI Premium Per User | B11: 6 | C11: Likely billable | D11: 0 | E11: =IF(B11=0,0,D11/B11) -> 0 | F11: Enter the monthly invoice amount for this SKU if it appears on the invoice
A12: Power Pages vTrial for Makers | B12: 5 | C12: Likely free / trial | D12: 0 | E12: =IF(B12=0,0,D12/B12) -> 0 | F12: Enter the monthly invoice amount for this SKU if it appears on the invoice
A13: Exchange Online (Plan 1) | B13: 4 | C13: Likely billable | D13: 0 | E13: =IF(B13=0,0,D13/B13) -> 0 | F13: Enter the monthly invoice amount for this SKU if it appears on the invoice
... A15: Power Automate per user plan | B15: 1 | C15: Likely billable | D15: 0 | E15: =IF(B15=0,0,D15/B15) -> 0 | F15: Enter the monthly invoice amount for this SKU if it appears on the invoice

Sheet User_Match
A1: Licensed Display Name | B1: Licensed Email | C1: Matched Employee Name | D1: Candidate Employee Email | E1: Employee Number | F1: Division | G1: Department Group | H1: Site | I1: Contact Number | J1: Match Status | K1: Confidence | L1: Review Required | M1: Mapping Note | N1: License SKU Count | O1: All Licenses Raw
A2: Antonio Ehrke | B2: Antonio.Ehrke@WearCheckRS.com | C2: Antonio Ehrke | D2: antonio.ehrke@wearcheckrs.com | E2: WC503 | F2: AFS | G2: AFS | I2: 0834695668 | J2: Matched | K2: High | L2: No | M2: Exact company email match | N2: 2 | O2: Microsoft Defender for Office 365 (Plan 2)+Microsoft 365 Business Standard
A3: Arnold van Zyl | B3: Arnold@WearCheckRS.com | C3: Arnoldus Johannes van Zyl | D3: Arnold@WearCheckRS.com | E3: WC526 | F3: AFS | G3: AFS | I3: 067412 1369 | J3: Matched | K3: High | L3: No | M3: Exact company email match | N3: 2 | O3: Microsoft Defender for Office 365 (Plan 2)+Microsoft 365 Business Standard
A4: Colleen Pyper | B4: colleen.pyper@WearCheckRS.com | C4: Colleen Pyper | D4: colleen.pyper@WearCheckRS.com | E4: WC486 | F4: AFS | G4: AFS | I4: 0662916811 | J4: Matched | K4: High | L4: No | M4: Exact company email match | N4: 3 | O4: Microsoft Defender for Office 365 (Plan 2)+Microsoft Power Automate Free+Microsoft 365 Business Standard
A5: Edwin Gibbons | B5: edwin@WearCheckRS.com | C5: Edwin Ashley Gibbons | D5: edwin@wearcheckrs.com | E5: WEC138 | F5: AFS | G5: AFS | I5: 0725336075 | J5: Matched | K5: High | L5: No | M5: Exact company email match | N5: 2 | O5: Microsoft Defender for Office 365 (Plan 2)+Microsoft 365 Business Standard
A6: Ethel Mienie | B6: ethel.mienie@WearCheckRS.com | C6: Ethel Mienie | D6: ethel.mienie@WearCheckRS.com | E6: WC488 | F6: AFS | G6: AFS | I6: 0660215452 | J6: Matched | K6: High | L6: No | M6: Exact company email match | N6: 2 | O6: Microsoft Defender for Office 365 (Plan 2)+Microsoft 365 Business Standard
A7: Evert Viljoen | B7: Evert@WearCheckRS.com | C7: Evert Viljoen | D7: evertv@wearcheck.co.za | E7: WC497 | F7: AFS | G7: AFS | I7: 0795284219 | J7: Matched | K7: Medium | L7: No | M7: Matched via exact name | N7: 2 | O7: Microsoft Defender for Office 365 (Plan 2)+Microsoft 365 Business Premium
A8: Godfrey Boikhutso | B8: Godfrey@WearCheckRS.com | C8: Godfrey Boikhutso | D8: godfreyb@wearcheck.co.za | E8: WC510 | F8: AFS | G8: AFS | I8: 0718609242 | J8: Matched | K8: Medium | L8: No | M8: Matched via exact name | N8: 2 | O8: Microsoft Defender for Office 365 (Plan 2)+Microsoft 365 Business Premium
A9: Jaco Venter | B9: JacoV@WearCheckRS.com | C9: Jacobus Frederick Venter | D9: jacov@wearcheck.co.za | E9: WC493 | F9: AFS | G9: AFS | I9: 0834009604 | J9: Matched | K9: Medium | L9: No | M9: Matched via email alias/local-part | N9: 2 | O9: Microsoft Defender for Office 365 (Plan 2)+Microsoft 365 Business Premium
A10: Johan Bekker | B10: JohanB@WearCheckRS.com | C10: Johan Bekker | D10: JohanB@wearcheckRS.com | E10: WC645 | F10: AFS | G10: AFS | I10: 0675951633 | J10: Matched | K10: High | L10: No | M10: Exact company email match | N10: 3 | O10: Microsoft Defender for Office 365 (Plan 2)+Microsoft Power Automate Free+Microsoft 365 Business Standard
A11: Johan Rossouw | B11: JohanR@WearCheckRS.com | C11: Johan Rossouw | D11: johanr@wearcheckrs.com | E11: WC491 | F11: AFS | G11: AFS | I11: 0829274240 | J11: Matched | K11: High | L11: No | M11: Exact company email match | N11: 2 | O11: Microsoft Defender for Office 365 (Plan 2)+Microsoft 365 Business Standard
A12: Khotso Mosala | B12: Khotso@WearCheckRS.com | C12: Khotso Thabo Mosala | D12: khotso@wearcheckrs.com | E12: WC482 | F12: AFS | G12: AFS | I12: 0823321905 | J12: Matched | K12: High | L12: No | M12: Exact company email match | N12: 2 | O12: Microsoft Defender for Office 365 (Plan 2)+Microsoft 365 Business Standard
A13: Landus Walters | B13: Landus@WearCheckRS.com | C13: Norman Landus Walters | D13: Landus@wearcheckrs.com | E13: WC509 | F13: AFS | G13: AFS | I13: 076 385 2151 | J13: Matched | K13: High | L13: No | M13: Exact company email match | N13: 2 | O13: Microsoft Defender for Office 365 (Plan 2)+Microsoft 365 Business Standard
... A20: Teresa Venter | B20: teresa.venter@WearCheckRS.com | C20: Teresa Venter | D20: teresa.venter@wearcheckRS.com | E20: WC487 | F20: AFS | G20: AFS | I20: 0662916929 | J20: Matched | K20: High | L20: No | M20: Exact company email match | N20: 3 | O20: Microsoft Defender for Office 365 (Plan 2)+Microsoft Power Automate Free+Microsoft 365 Business Standard
A21: Jean Pierre Du Plessis | B21: Jean-Pierre@WearCheckRS.com | C21: Jean Pierre du Plessis | F21: AFS | G21: AFS | I21: 0602033229 | J21: Matched | K21: Low | L21: Yes | M21: Matched via exact name | N21: 2 | O21: Microsoft 365 Business Standard+Microsoft Defender for Office 365 (Plan 2)
A22: Joe Kies | B22: Joe@WearCheckRS.com | C22: Joseph Benjamin Kies | D22: josephk@wearcheck.co.za | E22: WC531 | F22: AFS | G22: AFS | I22: 0674121368 | J22: Matched | K22: Low | L22: Yes | M22: Matched via manual alias/name rule | N22: 9 | O22: Microsoft Power Automate Free+Microsoft 365 Business Standard+Microsoft Power Apps Plan 2 Trial+Microsoft Fabric (Free)+Microsoft Copilot Studio Viral Trial+Microsoft Power Apps for Developer+Power Pages vTrial for Makers+Microsoft Defender for Office 365 (Plan 2)+Dynamics 365 Customer Insights Self-Service
A23: Johan Stols | B23: Johan.Stols@WearCheckRS.com | C23: Johannes Gideon Francios Stols | D23: Johans@wearcheckrs.com | E23: WC508 | F23: AFS | G23: AFS | I23: 0832943748 | J23: Matched | K23: Low | L23: Yes | M23: Matched via manual alias/name rule | N23: 3 | O23: Microsoft Defender for Office 365 (Plan 2)+Microsoft Power Automate Free+Microsoft 365 Business Standard
A24: Lorraine Mokgethi | B24: Lorraine@WearCheckRS.com | C24: Lorraine Lerato Mokgethi | D24: lorrainem@wearcheck.co.za | E24: WC495 | F24: AFS | G24: AFS | I24: 786 672 158 | J24: Matched | K24: Low | L24: Yes | M24: Matched via close email alias + surname | N24: 2 | O24: Microsoft Defender for Office 365 (Plan 2)+Microsoft 365 Business Premium
A25: Mervyn Gibbons | B25: Mervyn@WearCheckRS.com | C25: Mervyn Thomas Gibbons | D25: mervyng@wearcheck.co.za | E25: WC536 | F25: AFS | G25: AFS | I25: 0674193633 | J25: Matched | K25: Low | L25: Yes | M25: Matched via close email alias + surname | N25: 9 | O25: Microsoft Power Automate Free+Microsoft 365 Business Standard+Microsoft Power Apps Plan 2 Trial+Microsoft Fabric (Free)+Microsoft Copilot Studio Viral Trial+Microsoft Power Apps for Developer+Power Pages vTrial for Makers+Microsoft Defender for Office 365 (Plan 2)+Dynamics 365 Customer Insights Self-Service
A26: Armindo Mucacho | B26: Armindo@WearCheckRS.com | C26: Armindo Muchacho | D26: armindo@wearcheckrs.com | E26: Unknown | F26: Mozambique | G26: WearCheck | H26: Mozambique | I26: 258848349643 | J26: Matched | K26: High | L26: No | M26: Exact company email match | N26: 3 | O26: Microsoft Defender for Office 365 (Plan 2)+Microsoft Fabric (Free)+Microsoft 365 Business Standard
A27: David Lipange | B27: DavidL@WearCheckRS.com | C27: David Lipague | D27: davidl@wearcheckrs.com | E27: Unknown | F27: Mozambique | G27: WearCheck | H27: Mozambique | I27: 258847817888 | J27: Matched | K27: High | L27: No | M27: Exact company email match | N27: 3 | O27: Microsoft Defender for Office 365 (Plan 2)+Microsoft Fabric (Free)+Microsoft 365 Business Standard
A28: Isac Zacarias | B28: Isac@WearCheckRS.com | C28: Isac Zacarias | D28: isac@wearcheckrs.com | E28: Unknown | F28: Mozambique | G28: WearCheck | H28: Mozambique | I28: 258849439848 | J28: Matched | K28: High | L28: No | M28: Exact company email match | N28: 3 | O28: Microsoft Defender for Office 365 (Plan 2)+Microsoft Fabric (Free)+Microsoft 365 Business Standard
A29: Muhamad Ikram Hanif | B29: Muhamad@WearCheckRS.com | C29: Muhamad Hanif | D29: Muhamad@wearcheckRS.com | E29: Unknown | F29: Mozambique | G29: WearCheck | H29: Mozambique | I29: 258878054903 | J29: Matched | K29: High | L29: No | M29: Exact company email match | N29: 3 | O29: Microsoft Defender for Office 365 (Plan 2)+Microsoft Fabric (Free)+Microsoft 365 Business Standard
A30: Placido Maculuve | B30: Placido@WearCheckRS.com | C30: Placido Maculuve | D30: Placido@wearcheckrs.com | E30: Unknown | F30: Mozambique | G30: WearCheck | H30: Mozambique | I30: 258845070300 | J30: Matched | K30: High | L30: No | M30: Exact company email match | N30: 3 | O30: Microsoft Defender for Office 365 (Plan 2)+Microsoft Fabric (Free)+Microsoft 365 Business Standard
A31: Riaan Du Plooy | B31: RiaanDP@WearCheckRS.com | C31: Adriaan Johannes du Plooy | D31: Riaandp@wearcheckRS.com | E31: WC591 | F31: Mozambique | G31: WearCheck | H31: Mozambique | I31: 0835965562 | J31: Matched | K31: High | L31: No | M31: Exact company email match | N31: 2 | O31: Microsoft 365 Business Premium+Microsoft Defender for Office 365 (Plan 2)
A32: Dian Leff | B32: dian@WearCheckRS.com | C32: Dian Leff | D32: dian@wearcheckrs.com | E32: WCN008 | F32: Namibia | G32: WearCheck | H32: Namibia | I32: 0817614612 | J32: Matched | K32: High | L32: No | M32: Exact company email match | N32: 2 | O32: Microsoft Defender for Office 365 (Plan 2)+Microsoft 365 Business Standard
A33: Freddy-Ben Gariseb | B33: Freddy-Ben@WearCheckRS.com | C33: Freddy-Ben Gariseb | D33: Freddy-Ben@wearcheckRS.com | E33: WCN004 | F33: Namibia | G33: WearCheck | H33: Namibia | I33: 264813707010 | J33: Matched | K33: High | L33: No | M33: Exact company email match | N33: 2 | O33: Microsoft Defender for Office 365 (Plan 2)+Microsoft 365 Business Standard
A34: Gabriel | B34: Gabriel@WearCheckRS.com | C34: Gabriel Shikongo Nuunyango | D34: gabriel@wearcheckrs.com | E34: WCN007 | F34: Namibia | G34: WearCheck | H34: Namibia | I34: +264 81 364 5524 | J34: Matched | K34: High | L34: No | M34: Exact company email match | N34: 3 | O34: Microsoft Defender for Office 365 (Plan 2)+Microsoft Fabric (Free)+Microsoft 365 Business Standard
A35: Rohan Willer | B35: rohan@WearCheckRS.com | C35: Hermanus Johannes Willer | D35: rohan@wearcheckrs.com | E35: WC381 | F35: Namibia | G35: WearCheck | H35: Namibia | I35: 0812165890 | J35: Matched | K35: High | L35: No | M35: Exact company email match | N35: 3 | O35: Microsoft 365 Business Premium+Microsoft Defender for Office 365 (Plan 2)+Microsoft Power Automate Free
A36: AFS Application | B36: afs_app@WearCheckRS.com | F36: AFS | J36: Mapped by rule | K36: High | L36: No | M36: Generic/shared/service account defaulted to RS per instruction | N36: 2 | O36: Microsoft Power Automate Free+Exchange Online (Plan 1)
A37: Admin | B37: admin@WearCheckRS.com | F37: RS | J37: Mapped by rule | K37: High | L37: No | M37: Generic/shared/service account defaulted to RS per instruction | N37: 3 | O37: Microsoft Defender for Office 365 (Plan 2)+Microsoft Fabric (Free)+Microsoft 365 E3
A38: Adri Ludick | B38: A.Ludick@WearCheckRS.com | C38: Adri Ludick | D38: a.ludick@wearcheckRS.com | E38: WC492 | F38: RS | G38: GP Consult | I38: 0832816896 | J38: Matched | K38: High | L38: No | M38: Exact company email match | N38: 4 | O38: Microsoft 365 Business Premium+Microsoft Copilot Studio Viral Trial+Microsoft Defender for Office 365 (Plan 2)+Microsoft Power Automate Free
A39: Adriaan Bouwer | B39: adriaanb@WearCheckRS.com | C39: Adriaan Pertus Johannes Bouwer | D39: adriaanb@wearcheckrs.com | E39: WC383 | F39: RS | G39: WearCheck | H39: KwaZulu Natal | I39: 0608498504 | J39: Matched | K39: High | L39: No | M39: Exact company email match | N39: 4 | O39: Microsoft Defender for Office 365 (Plan 2)+Microsoft Power Automate Free+Microsoft 365 Business Standard+Microsoft Fabric (Free)
A40: Alex Outram | B40: Alex@WearCheckRS.com | C40: Alexander Outram | D40: alex@wearcheckrs.com | E40: WEC105 | F40: RS | G40: GP Consult | H40: RBMR and PMR | I40: 0662213616 / 0720164289 | J40: Matched | K40: High | L40: No | M40: Exact company email match | N40: 4 | O40: Microsoft Defender for Office 365 (Plan 2)+Microsoft Power Automate Free+Microsoft Fabric (Free)+Microsoft 365 Business Standard
A41: Allan Stuurman | B41: Allan@WearCheckRS.com | C41: Allan Stuurman | D41: allan@wearcheckrs.com | E41: WEC123 | F41: RS | G41: GP Consult | H41: Samancor - ECM Tweefontein | I41: 0799121301 | J41: Matched | K41: High | L41: No | M41: Exact company email match | N41: 2 | O41: Microsoft Defender for Office 365 (Plan 2)+Microsoft 365 Business Standard
A42: Andrew Robb | B42: Andrew@wearcheckrs.com | C42: Andrew John Walker Robb | D42: andrew@wearcheckRS.com | E42: WEC103 | F42: RS | G42: GP Consult | H42: Remote Centre | I42: 0636504444 | J42: Matched | K42: High | L42: No | M42: Exact company email match | N42: 3 | O42: Microsoft 365 Business Premium+Microsoft Defender for Office 365 (Plan 2)+Microsoft Fabric (Free)
A43: Annah Modutwane | B43: annahm@WearCheckRS.com | C43: Annah Seipone Modutwane | D43: annahm@wearcheckrs.com | E43: WC484 | F43: RS | G43: WearCheck | H43: Valterra - Mototolo | I43: 0833579812 | J43: Matched | K43: High | L43: No | M43: Exact company email match | N43: 4 | O43: Microsoft Defender for Office 365 (Plan 2)+Microsoft Power Automate Free+Microsoft Fabric (Free)+Microsoft 365 Business Standard
A44: Annemie Willer | B44: annemie@WearCheckRS.com | C44: Annemie Willer | D44: annemie@wearcheckrs.com | E44: WC319 | F44: RS | G44: WearCheck | H44: Longmeadow H/O | I44: 0716096197 | J44: Matched | K44: High | L44: No | M44: Exact company email match | N44: 7 | O44: Microsoft Defender for Office 365 (Plan 2)+Power BI Premium Per User+Microsoft Copilot Studio Viral Trial+Microsoft Power Apps Plan 2 Trial+Microsoft 365 E3+Microsoft Fabric (Free)+Microsoft Power Automate Free
A45: Aubrey Tshabalala | B45: Aubrey@WearCheckRS.com | C45: Aubrey Tshabalala | D45: aubrey@wearcheckRS.com | E45: WEC114 | F45: RS | G45: GP Consult | H45: Valterra - Mototolo | I45: 0824871527 | J45: Matched | K45: High | L45: No | M45: Exact company email match | N45: 2 | O45: Microsoft Defender for Office 365 (Plan 2)+Microsoft 365 Business Standard
A46: Bernard Lopi Molangoane | B46: lopi@WearCheckRS.com | C46: Bernard Lopi Molangoane | D46: lopim@wearcheck.co.za | E46: WC269 | F46: RS | G46: WearCheck | H46: Valterra - Mototolo | I46: 0636888886 | J46: Matched | K46: Medium | L46: No | M46: Matched via exact name | N46: 2 | O46: Microsoft Defender for Office 365 (Plan 2)+Microsoft 365 Business Standard
...

Sheet Allocation_Detail
A1: Licensed Email | B1: Licensed Display Name | C1: Division | D1: Employee Number | E1: Match Status | F1: Review Required | G1: SKU | H1: Billing Hint | I1: Monthly Invoice Amount | J1: Active Users on SKU | K1: Unit Cost | L1: Allocated Cost | M1: Mapping Note
A2: Antonio.Ehrke@WearCheckRS.com | B2: Antonio Ehrke | C2: AFS | D2: WC503 | E2: Matched | F2: No | G2: Microsoft Defender for Office 365 (Plan 2) | H2: Review invoice | I2: =IFERROR(VLOOKUP(G2,SKU_Cost_Input!$A$2:$E$15,4,FALSE),0) -> 0 | J2: =IFERROR(VLOOKUP(G2,SKU_Cost_Input!$A$2:$E$15,2,FALSE),0) -> 130 | K2: =IF(J2=0,0,I2/J2) -> 0 | L2: =K2 -> 0 | M2: Exact company email match
A3: Antonio.Ehrke@WearCheckRS.com | B3: Antonio Ehrke | C3: AFS | D3: WC503 | E3: Matched | F3: No | G3: Microsoft 365 Business Standard | H3: Likely billable | I3: =IFERROR(VLOOKUP(G3,SKU_Cost_Input!$A$2:$E$15,4,FALSE),0) -> 0 | J3: =IFERROR(VLOOKUP(G3,SKU_Cost_Input!$A$2:$E$15,2,FALSE),0) -> 100 | K3: =IF(J3=0,0,I3/J3) -> 0 | L3: =K3 -> 0 | M3: Exact company email match
A4: Arnold@WearCheckRS.com | B4: Arnold van Zyl | C4: AFS | D4: WC526 | E4: Matched | F4: No | G4: Microsoft Defender for Office 365 (Plan 2) | H4: Review invoice | I4: =IFERROR(VLOOKUP(G4,SKU_Cost_Input!$A$2:$E$15,4,FALSE),0) -> 0 | J4: =IFERROR(VLOOKUP(G4,SKU_Cost_Input!$A$2:$E$15,2,FALSE),0) -> 130 | K4: =IF(J4=0,0,I4/J4) -> 0 | L4: =K4 -> 0 | M4: Exact company email match
A5: Arnold@WearCheckRS.com | B5: Arnold van Zyl | C5: AFS | D5: WC526 | E5: Matched | F5: No | G5: Microsoft 365 Business Standard | H5: Likely billable | I5: =IFERROR(VLOOKUP(G5,SKU_Cost_Input!$A$2:$E$15,4,FALSE),0) -> 0 | J5: =IFERROR(VLOOKUP(G5,SKU_Cost_Input!$A$2:$E$15,2,FALSE),0) -> 100 | K5: =IF(J5=0,0,I5/J5) -> 0 | L5: =K5 -> 0 | M5: Exact company email match
A6: colleen.pyper@WearCheckRS.com | B6: Colleen Pyper | C6: AFS | D6: WC486 | E6: Matched | F6: No | G6: Microsoft Defender for Office 365 (Plan 2) | H6: Review invoice | I6: =IFERROR(VLOOKUP(G6,SKU_Cost_Input!$A$2:$E$15,4,FALSE),0) -> 0 | J6: =IFERROR(VLOOKUP(G6,SKU_Cost_Input!$A$2:$E$15,2,FALSE),0) -> 130 | K6: =IF(J6=0,0,I6/J6) -> 0 | L6: =K6 -> 0 | M6: Exact company email match
A7: colleen.pyper@WearCheckRS.com | B7: Colleen Pyper | C7: AFS | D7: WC486 | E7: Matched | F7: No | G7: Microsoft Power Automate Free | H7: Likely free / trial | I7: =IFERROR(VLOOKUP(G7,SKU_Cost_Input!$A$2:$E$15,4,FALSE),0) -> 0 | J7: =IFERROR(VLOOKUP(G7,SKU_Cost_Input!$A$2:$E$15,2,FALSE),0) -> 52 | K7: =IF(J7=0,0,I7/J7) -> 0 | L7: =K7 -> 0 | M7: Exact company email match
A8: colleen.pyper@WearCheckRS.com | B8: Colleen Pyper | C8: AFS | D8: WC486 | E8: Matched | F8: No | G8: Microsoft 365 Business Standard | H8: Likely billable | I8: =IFERROR(VLOOKUP(G8,SKU_Cost_Input!$A$2:$E$15,4,FALSE),0) -> 0 | J8: =IFERROR(VLOOKUP(G8,SKU_Cost_Input!$A$2:$E$15,2,FALSE),0) -> 100 | K8: =IF(J8=0,0,I8/J8) -> 0 | L8: =K8 -> 0 | M8: Exact company email match
A9: edwin@WearCheckRS.com | B9: Edwin Gibbons | C9: AFS | D9: WEC138 | E9: Matched | F9: No | G9: Microsoft Defender for Office 365 (Plan 2) | H9: Review invoice | I9: =IFERROR(VLOOKUP(G9,SKU_Cost_Input!$A$2:$E$15,4,FALSE),0) -> 0 | J9: =IFERROR(VLOOKUP(G9,SKU_Cost_Input!$A$2:$E$15,2,FALSE),0) -> 130 | K9: =IF(J9=0,0,I9/J9) -> 0 | L9: =K9 -> 0 | M9: Exact company email match
A10: edwin@WearCheckRS.com | B10: Edwin Gibbons | C10: AFS | D10: WEC138 | E10: Matched | F10: No | G10: Microsoft 365 Business Standard | H10: Likely billable | I10: =IFERROR(VLOOKUP(G10,SKU_Cost_Input!$A$2:$E$15,4,FALSE),0) -> 0 | J10: =IFERROR(VLOOKUP(G10,SKU_Cost_Input!$A$2:$E$15,2,FALSE),0) -> 100 | K10: =IF(J10=0,0,I10/J10) -> 0 | L10: =K10 -> 0 | M10: Exact company email match
A11: ethel.mienie@WearCheckRS.com | B11: Ethel Mienie | C11: AFS | D11: WC488 | E11: Matched | F11: No | G11: Microsoft Defender for Office 365 (Plan 2) | H11: Review invoice | I11: =IFERROR(VLOOKUP(G11,SKU_Cost_Input!$A$2:$E$15,4,FALSE),0) -> 0 | J11: =IFERROR(VLOOKUP(G11,SKU_Cost_Input!$A$2:$E$15,2,FALSE),0) -> 130 | K11: =IF(J11=0,0,I11/J11) -> 0 | L11: =K11 -> 0 | M11: Exact company email match
A12: ethel.mienie@WearCheckRS.com | B12: Ethel Mienie | C12: AFS | D12: WC488 | E12: Matched | F12: No | G12: Microsoft 365 Business Standard | H12: Likely billable | I12: =IFERROR(VLOOKUP(G12,SKU_Cost_Input!$A$2:$E$15,4,FALSE),0) -> 0 | J12: =IFERROR(VLOOKUP(G12,SKU_Cost_Input!$A$2:$E$15,2,FALSE),0) -> 100 | K12: =IF(J12=0,0,I12/J12) -> 0 | L12: =K12 -> 0 | M12: Exact company email match
A13: Evert@WearCheckRS.com | B13: Evert Viljoen | C13: AFS | D13: WC497 | E13: Matched | F13: No | G13: Microsoft Defender for Office 365 (Plan 2) | H13: Review invoice | I13: =IFERROR(VLOOKUP(G13,SKU_Cost_Input!$A$2:$E$15,4,FALSE),0) -> 0 | J13: =IFERROR(VLOOKUP(G13,SKU_Cost_Input!$A$2:$E$15,2,FALSE),0) -> 130 | K13: =IF(J13=0,0,I13/J13) -> 0 | L13: =K13 -> 0 | M13: Matched via exact name
... A43: teresa.venter@WearCheckRS.com | B43: Teresa Venter | C43: AFS | D43: WC487 | E43: Matched | F43: No | G43: Microsoft 365 Business Standard | H43: Likely billable | I43: =IFERROR(VLOOKUP(G43,SKU_Cost_Input!$A$2:$E$15,4,FALSE),0) -> 0 | J43: =IFERROR(VLOOKUP(G43,SKU_Cost_Input!$A$2:$E$15,2,FALSE),0) -> 100 | K43: =IF(J43=0,0,I43/J43) -> 0 | L43: =K43 -> 0 | M43: Exact company email match
A44: Jean-Pierre@WearCheckRS.com | B44: Jean Pierre Du Plessis | C44: AFS | E44: Matched | F44: Yes | G44: Microsoft 365 Business Standard | H44: Likely billable | I44: =IFERROR(VLOOKUP(G44,SKU_Cost_Input!$A$2:$E$15,4,FALSE),0) -> 0 | J44: =IFERROR(VLOOKUP(G44,SKU_Cost_Input!$A$2:$E$15,2,FALSE),0) -> 100 | K44: =IF(J44=0,0,I44/J44) -> 0 | L44: =K44 -> 0 | M44: Matched via exact name
A45: Jean-Pierre@WearCheckRS.com | B45: Jean Pierre Du Plessis | C45: AFS | E45: Matched | F45: Yes | G45: Microsoft Defender for Office 365 (Plan 2) | H45: Review invoice | I45: =IFERROR(VLOOKUP(G45,SKU_Cost_Input!$A$2:$E$15,4,FALSE),0) -> 0 | J45: =IFERROR(VLOOKUP(G45,SKU_Cost_Input!$A$2:$E$15,2,FALSE),0) -> 130 | K45: =IF(J45=0,0,I45/J45) -> 0 | L45: =K45 -> 0 | M45: Matched via exact name
A46: Joe@WearCheckRS.com | B46: Joe Kies | C46: AFS | D46: WC531 | E46: Matched | F46: Yes | G46: Microsoft Power Automate Free | H46: Likely free / trial | I46: =IFERROR(VLOOKUP(G46,SKU_Cost_Input!$A$2:$E$15,4,FALSE),0) -> 0 | J46: =IFERROR(VLOOKUP(G46,SKU_Cost_Input!$A$2:$E$15,2,FALSE),0) -> 52 | K46: =IF(J46=0,0,I46/J46) -> 0 | L46: =K46 -> 0 | M46: Matched via manual alias/name rule
A47: Joe@WearCheckRS.com | B47: Joe Kies | C47: AFS | D47: WC531 | E47: Matched | F47: Yes | G47: Microsoft 365 Business Standard | H47: Likely billable | I47: =IFERROR(VLOOKUP(G47,SKU_Cost_Input!$A$2:$E$15,4,FALSE),0) -> 0 | J47: =IFERROR(VLOOKUP(G47,SKU_Cost_Input!$A$2:$E$15,2,FALSE),0) -> 100 | K47: =IF(J47=0,0,I47/J47) -> 0 | L47: =K47 -> 0 | M47: Matched via manual alias/name rule
A48: Joe@WearCheckRS.com | B48: Joe Kies | C48: AFS | D48: WC531 | E48: Matched | F48: Yes | G48: Microsoft Power Apps Plan 2 Trial | H48: Likely free / trial | I48: =IFERROR(VLOOKUP(G48,SKU_Cost_Input!$A$2:$E$15,4,FALSE),0) -> 0 | J48: =IFERROR(VLOOKUP(G48,SKU_Cost_Input!$A$2:$E$15,2,FALSE),0) -> 6 | K48: =IF(J48=0,0,I48/J48) -> 0 | L48: =K48 -> 0 | M48: Matched via manual alias/name rule
A49: Joe@WearCheckRS.com | B49: Joe Kies | C49: AFS | D49: WC531 | E49: Matched | F49: Yes | G49: Microsoft Fabric (Free) | H49: Likely free / trial | I49: =IFERROR(VLOOKUP(G49,SKU_Cost_Input!$A$2:$E$15,4,FALSE),0) -> 0 | J49: =IFERROR(VLOOKUP(G49,SKU_Cost_Input!$A$2:$E$15,2,FALSE),0) -> 50 | K49: =IF(J49=0,0,I49/J49) -> 0 | L49: =K49 -> 0 | M49: Matched via manual alias/name rule
A50: Joe@WearCheckRS.com | B50: Joe Kies | C50: AFS | D50: WC531 | E50: Matched | F50: Yes | G50: Microsoft Copilot Studio Viral Trial | H50: Likely free / trial | I50: =IFERROR(VLOOKUP(G50,SKU_Cost_Input!$A$2:$E$15,4,FALSE),0) -> 0 | J50: =IFERROR(VLOOKUP(G50,SKU_Cost_Input!$A$2:$E$15,2,FALSE),0) -> 7 | K50: =IF(J50=0,0,I50/J50) -> 0 | L50: =K50 -> 0 | M50: Matched via manual alias/name rule
A51: Joe@WearCheckRS.com | B51: Joe Kies | C51: AFS | D51: WC531 | E51: Matched | F51: Yes | G51: Microsoft Power Apps for Developer | H51: Review invoice | I51: =IFERROR(VLOOKUP(G51,SKU_Cost_Input!$A$2:$E$15,4,FALSE),0) -> 0 | J51: =IFERROR(VLOOKUP(G51,SKU_Cost_Input!$A$2:$E$15,2,FALSE),0) -> 6 | K51: =IF(J51=0,0,I51/J51) -> 0 | L51: =K51 -> 0 | M51: Matched via manual alias/name rule
A52: Joe@WearCheckRS.com | B52: Joe Kies | C52: AFS | D52: WC531 | E52: Matched | F52: Yes | G52: Power Pages vTrial for Makers | H52: Likely free / trial | I52: =IFERROR(VLOOKUP(G52,SKU_Cost_Input!$A$2:$E$15,4,FALSE),0) -> 0 | J52: =IFERROR(VLOOKUP(G52,SKU_Cost_Input!$A$2:$E$15,2,FALSE),0) -> 5 | K52: =IF(J52=0,0,I52/J52) -> 0 | L52: =K52 -> 0 | M52: Matched via manual alias/name rule
A53: Joe@WearCheckRS.com | B53: Joe Kies | C53: AFS | D53: WC531 | E53: Matched | F53: Yes | G53: Microsoft Defender for Office 365 (Plan 2) | H53: Review invoice | I53: =IFERROR(VLOOKUP(G53,SKU_Cost_Input!$A$2:$E$15,4,FALSE),0) -> 0 | J53: =IFERROR(VLOOKUP(G53,SKU_Cost_Input!$A$2:$E$15,2,FALSE),0) -> 130 | K53: =IF(J53=0,0,I53/J53) -> 0 | L53: =K53 -> 0 | M53: Matched via manual alias/name rule
A54: Joe@WearCheckRS.com | B54: Joe Kies | C54: AFS | D54: WC531 | E54: Matched | F54: Yes | G54: Dynamics 365 Customer Insights Self-Service | H54: Review invoice | I54: =IFERROR(VLOOKUP(G54,SKU_Cost_Input!$A$2:$E$15,4,FALSE),0) -> 0 | J54: =IFERROR(VLOOKUP(G54,SKU_Cost_Input!$A$2:$E$15,2,FALSE),0) -> 3 | K54: =IF(J54=0,0,I54/J54) -> 0 | L54: =K54 -> 0 | M54: Matched via manual alias/name rule
A55: Johan.Stols@WearCheckRS.com | B55: Johan Stols | C55: AFS | D55: WC508 | E55: Matched | F55: Yes | G55: Microsoft Defender for Office 365 (Plan 2) | H55: Review invoice | I55: =IFERROR(VLOOKUP(G55,SKU_Cost_Input!$A$2:$E$15,4,FALSE),0) -> 0 | J55: =IFERROR(VLOOKUP(G55,SKU_Cost_Input!$A$2:$E$15,2,FALSE),0) -> 130 | K55: =IF(J55=0,0,I55/J55) -> 0 | L55: =K55 -> 0 | M55: Matched via manual alias/name rule
A56: Johan.Stols@WearCheckRS.com | B56: Johan Stols | C56: AFS | D56: WC508 | E56: Matched | F56: Yes | G56: Microsoft Power Automate Free | H56: Likely free / trial | I56: =IFERROR(VLOOKUP(G56,SKU_Cost_Input!$A$2:$E$15,4,FALSE),0) -> 0 | J56: =IFERROR(VLOOKUP(G56,SKU_Cost_Input!$A$2:$E$15,2,FALSE),0) -> 52 | K56: =IF(J56=0,0,I56/J56) -> 0 | L56: =K56 -> 0 | M56: Matched via manual alias/name rule
A57: Johan.Stols@WearCheckRS.com | B57: Johan Stols | C57: AFS | D57: WC508 | E57: Matched | F57: Yes | G57: Microsoft 365 Business Standard | H57: Likely billable | I57: =IFERROR(VLOOKUP(G57,SKU_Cost_Input!$A$2:$E$15,4,FALSE),0) -> 0 | J57: =IFERROR(VLOOKUP(G57,SKU_Cost_Input!$A$2:$E$15,2,FALSE),0) -> 100 | K57: =IF(J57=0,0,I57/J57) -> 0 | L57: =K57 -> 0 | M57: Matched via manual alias/name rule
... A95: rohan@WearCheckRS.com | B95: Rohan Willer | C95: Namibia | D95: WC381 | E95: Matched | F95: No | G95: Microsoft Power Automate Free | H95: Likely free / trial | I95: =IFERROR(VLOOKUP(G95,SKU_Cost_Input!$A$2:$E$15,4,FALSE),0) -> 0 | J95: =IFERROR(VLOOKUP(G95,SKU_Cost_Input!$A$2:$E$15,2,FALSE),0) -> 52 | K95: =IF(J95=0,0,I95/J95) -> 0 | L95: =K95 -> 0 | M95: Exact company email match
A96: afs_app@WearCheckRS.com | B96: AFS Application | C96: RS | E96: Mapped by rule | F96: No | G96: Microsoft Power Automate Free | H96: Likely free / trial | I96: =IFERROR(VLOOKUP(G96,SKU_Cost_Input!$A$2:$E$15,4,FALSE),0) -> 0 | J96: =IFERROR(VLOOKUP(G96,SKU_Cost_Input!$A$2:$E$15,2,FALSE),0) -> 52 | K96: =IF(J96=0,0,I96/J96) -> 0 | L96: =K96 -> 0 | M96: Generic/shared/service account defaulted to RS per instruction
A97: afs_app@WearCheckRS.com | B97: AFS Application | C97: RS | E97: Mapped by rule | F97: No | G97: Exchange Online (Plan 1) | H97: Likely billable | I97: =IFERROR(VLOOKUP(G97,SKU_Cost_Input!$A$2:$E$15,4,FALSE),0) -> 0 | J97: =IFERROR(VLOOKUP(G97,SKU_Cost_Input!$A$2:$E$15,2,FALSE),0) -> 4 | K97: =IF(J97=0,0,I97/J97) -> 0 | L97: =K97 -> 0 | M97: Generic/shared/service account defaulted to RS per instruction
A98: admin@WearCheckRS.com | B98: Admin | C98: RS | E98: Mapped by rule | F98: No | G98: Microsoft Defender for Office 365 (Plan 2) | H98: Review invoice | I98: =IFERROR(VLOOKUP(G98,SKU_Cost_Input!$A$2:$E$15,4,FALSE),0) -> 0 | J98: =IFERROR(VLOOKUP(G98,SKU_Cost_Input!$A$2:$E$15,2,FALSE),0) -> 130 | K98: =IF(J98=0,0,I98/J98) -> 0 | L98: =K98 -> 0 | M98: Generic/shared/service account defaulted to RS per instruction
A99: admin@WearCheckRS.com | B99: Admin | C99: RS | E99: Mapped by rule | F99: No | G99: Microsoft Fabric (Free) | H99: Likely free / trial | I99: =IFERROR(VLOOKUP(G99,SKU_Cost_Input!$A$2:$E$15,4,FALSE),0) -> 0 | J99: =IFERROR(VLOOKUP(G99,SKU_Cost_Input!$A$2:$E$15,2,FALSE),0) -> 50 | K99: =IF(J99=0,0,I99/J99) -> 0 | L99: =K99 -> 0 | M99: Generic/shared/service account defaulted to RS per instruction
A100: admin@WearCheckRS.com | B100: Admin | C100: RS | E100: Mapped by rule | F100: No | G100: Microsoft 365 E3 | H100: Likely billable | I100: =IFERROR(VLOOKUP(G100,SKU_Cost_Input!$A$2:$E$15,4,FALSE),0) -> 0 | J100: =IFERROR(VLOOKUP(G100,SKU_Cost_Input!$A$2:$E$15,2,FALSE),0) -> 14 | K100: =IF(J100=0,0,I100/J100) -> 0 | L100: =K100 -> 0 | M100: Generic/shared/service account defaulted to RS per instruction
A101: A.Ludick@WearCheckRS.com | B101: Adri Ludick | C101: RS | D101: WC492 | E101: Matched | F101: No | G101: Microsoft 365 Business Premium | H101: Likely billable | I101: =IFERROR(VLOOKUP(G101,SKU_Cost_Input!$A$2:$E$15,4,FALSE),0) -> 0 | J101: =IFERROR(VLOOKUP(G101,SKU_Cost_Input!$A$2:$E$15,2,FALSE),0) -> 21 | K101: =IF(J101=0,0,I101/J101) -> 0 | L101: =K101 -> 0 | M101: Exact company email match
A102: A.Ludick@WearCheckRS.com | B102: Adri Ludick | C102: RS | D102: WC492 | E102: Matched | F102: No | G102: Microsoft Copilot Studio Viral Trial | H102: Likely free / trial | I102: =IFERROR(VLOOKUP(G102,SKU_Cost_Input!$A$2:$E$15,4,FALSE),0) -> 0 | J102: =IFERROR(VLOOKUP(G102,SKU_Cost_Input!$A$2:$E$15,2,FALSE),0) -> 7 | K102: =IF(J102=0,0,I102/J102) -> 0 | L102: =K102 -> 0 | M102: Exact company email match
A103: A.Ludick@WearCheckRS.com | B103: Adri Ludick | C103: RS | D103: WC492 | E103: Matched | F103: No | G103: Microsoft Defender for Office 365 (Plan 2) | H103: Review invoice | I103: =IFERROR(VLOOKUP(G103,SKU_Cost_Input!$A$2:$E$15,4,FALSE),0) -> 0 | J103: =IFERROR(VLOOKUP(G103,SKU_Cost_Input!$A$2:$E$15,2,FALSE),0) -> 130 | K103: =IF(J103=0,0,I103/J103) -> 0 | L103: =K103 -> 0 | M103: Exact company email match
A104: A.Ludick@WearCheckRS.com | B104: Adri Ludick | C104: RS | D104: WC492 | E104: Matched | F104: No | G104: Microsoft Power Automate Free | H104: Likely free / trial | I104: =IFERROR(VLOOKUP(G104,SKU_Cost_Input!$A$2:$E$15,4,FALSE),0) -> 0 | J104: =IFERROR(VLOOKUP(G104,SKU_Cost_Input!$A$2:$E$15,2,FALSE),0) -> 52 | K104: =IF(J104=0,0,I104/J104) -> 0 | L104: =K104 -> 0 | M104: Exact company email match
A105: adriaanb@WearCheckRS.com | B105: Adriaan Bouwer | C105: RS | D105: WC383 | E105: Matched | F105: No | G105: Microsoft Defender for Office 365 (Plan 2) | H105: Review invoice | I105: =IFERROR(VLOOKUP(G105,SKU_Cost_Input!$A$2:$E$15,4,FALSE),0) -> 0 | J105: =IFERROR(VLOOKUP(G105,SKU_Cost_Input!$A$2:$E$15,2,FALSE),0) -> 130 | K105: =IF(J105=0,0,I105/J105) -> 0 | L105: =K105 -> 0 | M105: Exact company email match
A106: adriaanb@WearCheckRS.com | B106: Adriaan Bouwer | C106: RS | D106: WC383 | E106: Matched | F106: No | G106: Microsoft Power Automate Free | H106: Likely free / trial | I106: =IFERROR(VLOOKUP(G106,SKU_Cost_Input!$A$2:$E$15,4,FALSE),0) -> 0 | J106: =IFERROR(VLOOKUP(G106,SKU_Cost_Input!$A$2:$E$15,2,FALSE),0) -> 52 | K106: =IF(J106=0,0,I106/J106) -> 0 | L106: =K106 -> 0 | M106: Exact company email match
...

Sheet Review_Queue
A1: Licensed Display Name | B1: Licensed Email | C1: Suggested Division | D1: Matched Employee Name | E1: Candidate Employee Email | F1: Employee Number | G1: Confidence | H1: Review Type | I1: Mapping Note | J1: Licenses Raw
A2: Jean Pierre Du Plessis | B2: Jean-Pierre@WearCheckRS.com | C2: AFS | D2: Jean Pierre du Plessis | G2: Low | H2: Low confidence match | I2: Matched via exact name | J2: Microsoft 365 Business Standard+Microsoft Defender for Office 365 (Plan 2)
A3: Joe Kies | B3: Joe@WearCheckRS.com | C3: AFS | D3: Joseph Benjamin Kies | E3: josephk@wearcheck.co.za | F3: WC531 | G3: Low | H3: Low confidence match | I3: Matched via manual alias/name rule | J3: Microsoft Power Automate Free+Microsoft 365 Business Standard+Microsoft Power Apps Plan 2 Trial+Microsoft Fabric (Free)+Microsoft Copilot Studio Viral Trial+Microsoft Power Apps for Developer+Power Pages vTrial for Makers+Microsoft Defender for Office 365 (Plan 2)+Dynamics 365 Customer Insights Self-Service
A4: Johan Stols | B4: Johan.Stols@WearCheckRS.com | C4: AFS | D4: Johannes Gideon Francios Stols | E4: Johans@wearcheckrs.com | F4: WC508 | G4: Low | H4: Low confidence match | I4: Matched via manual alias/name rule | J4: Microsoft Defender for Office 365 (Plan 2)+Microsoft Power Automate Free+Microsoft 365 Business Standard
A5: Lorraine Mokgethi | B5: Lorraine@WearCheckRS.com | C5: AFS | D5: Lorraine Lerato Mokgethi | E5: lorrainem@wearcheck.co.za | F5: WC495 | G5: Low | H5: Low confidence match | I5: Matched via close email alias + surname | J5: Microsoft Defender for Office 365 (Plan 2)+Microsoft 365 Business Premium
A6: Mervyn Gibbons | B6: Mervyn@WearCheckRS.com | C6: AFS | D6: Mervyn Thomas Gibbons | E6: mervyng@wearcheck.co.za | F6: WC536 | G6: Low | H6: Low confidence match | I6: Matched via close email alias + surname | J6: Microsoft Power Automate Free+Microsoft 365 Business Standard+Microsoft Power Apps Plan 2 Trial+Microsoft Fabric (Free)+Microsoft Copilot Studio Viral Trial+Microsoft Power Apps for Developer+Power Pages vTrial for Makers+Microsoft Defender for Office 365 (Plan 2)+Dynamics 365 Customer Insights Self-Service
A7: Adri Ludick Old | B7: Adri.ludick@WearCheckRS.com | C7: Unassigned - Review | G7: Unassigned | H7: Unassigned / no confident match | I7: No employee match found in employee master | J7: Microsoft Defender for Office 365 (Plan 2)+Microsoft Power Automate Free+Microsoft 365 Business Standard
A8: Boitumelo Makgamatha | B8: Boitumelo@WearCheckRS.com | C8: Unassigned - Review | G8: Unassigned | H8: Unassigned / no confident match | I8: No employee match found in employee master | J8: Microsoft Defender for Office 365 (Plan 2)+Microsoft 365 Business Standard
A9: Christene Fourie | B9: Christene@WearCheckRS.com | C9: Unassigned - Review | E9: chrstene@wearcheckrs.com | G9: Unassigned | H9: Unassigned / no confident match | I9: Possible email alias match to chrstene@wearcheckrs.com | J9: Microsoft Defender for Office 365 (Plan 2)+Microsoft Power Automate Free+Microsoft 365 Business Standard
A10: Christian Geel | B10: Christian@WearCheckRS.com | C10: Unassigned - Review | G10: Unassigned | H10: Unassigned / no confident match | I10: No employee match found in employee master | J10: Microsoft Fabric (Free)+Microsoft Power Automate Free
A11: Christie | B11: christie.samancor@WearCheckRS.com | C11: Unassigned - Review | G11: Unassigned | H11: Unassigned / no confident match | I11: No employee match found in employee master | J11: Microsoft Fabric (Free)
A12: Gladwin Sekharume | B12: GladwinS@WearCheckRS.com | C12: Unassigned - Review | G12: Unassigned | H12: Unassigned / no confident match | I12: No employee match found in employee master | J12: Microsoft Defender for Office 365 (Plan 2)+Microsoft 365 Business Standard
A13: Ivan Langa | B13: Ivan@WearCheckRS.com | C13: Unassigned - Review | G13: Unassigned | H13: Unassigned / no confident match | I13: No employee match found in employee master | J13: Microsoft Defender for Office 365 (Plan 2)+Microsoft Fabric (Free)+Microsoft 365 Business Standard
A14: Kenneth Moremi | B14: kenneth@WearCheckRS.com | C14: Unassigned - Review | G14: Unassigned | H14: Unassigned / no confident match | I14: No employee match found in employee master | J14: Microsoft Defender for Office 365 (Plan 2)+Microsoft 365 Business Standard
A15: Kevin Jonker | B15: kevinj@WearCheckRS.com | C15: Unassigned - Review | E15: kevin@wearcheckrs.com | G15: Unassigned | H15: Unassigned / no confident match | I15: Possible email alias match to kevin@wearcheckrs.com | J15: Microsoft Fabric (Free)+Microsoft Power Automate Free
A16: Lea Bodenstein | B16: Lea@WearCheckRS.com | C16: Unassigned - Review | G16: Unassigned | H16: Unassigned / no confident match | I16: No employee match found in employee master | J16: Microsoft 365 Business Premium+Microsoft Defender for Office 365 (Plan 2)+Microsoft Fabric (Free)
A17: Mandiso Muchanga | B17: Mandiso@WearCheckRS.com | C17: Unassigned - Review | G17: Unassigned | H17: Unassigned / no confident match | I17: No employee match found in employee master | J17: Microsoft Defender for Office 365 (Plan 2)+Microsoft 365 Business Standard
A18: Marthinus Steenkamp | B18: Marthinus@WearCheckRS.com | C18: Unassigned - Review | G18: Unassigned | H18: Unassigned / no confident match | I18: No employee match found in employee master | J18: Microsoft Defender for Office 365 (Plan 2)+Microsoft 365 E3+Microsoft Fabric (Free)
A19: Martin Prinsloo | B19: martin.prinsloo@WearCheckRS.com | C19: Unassigned - Review | G19: Unassigned | H19: Unassigned / no confident match | I19: No employee match found in employee master | J19: Microsoft Fabric (Free)
A20: Nicolien Schutte | B20: Nicoliens@WearCheckRS.com | C20: Unassigned - Review | G20: Unassigned | H20: Unassigned / no confident match | I20: No employee match found in employee master | J20: Microsoft Defender for Office 365 (Plan 2)+Power BI Premium Per User+Microsoft 365 E3+Microsoft Fabric (Free)+Microsoft Power Automate Free
A21: Peter | B21: Peter@WearCheckRS.com | C21: Unassigned - Review | G21: Unassigned | H21: Unassigned / no confident match | I21: No employee match found in employee master | J21: Microsoft 365 Business Standard
A22: Stephanie Du Plessis | B22: stephanied@wearcheckrs.com | C22: Unassigned - Review | G22: Unassigned | H22: Unassigned / no confident match | I22: No employee match found in employee master | J22: Microsoft 365 Business Standard+Microsoft Defender for Office 365 (Plan 2)
A23: Thabang Mathumba | B23: thabang@WearCheckRS.com | C23: Unassigned - Review | G23: Unassigned | H23: Unassigned / no confident match | I23: No employee match found in employee master | J23: Microsoft Defender for Office 365 (Plan 2)+Microsoft 365 Business Standard
A24: Tumelo | B24: tumelo.samancor@WearCheckRS.com | C24: Unassigned - Review | G24: Unassigned | H24: Unassigned / no confident match | I24: No employee match found in employee master | J24: Microsoft Fabric (Free)

Sheet Employee_Master
A1: Company Email | B1: Employee Name | C1: Employee Code | D1: Department 1 | E1: Department 2 | F1: Site | G1: Derived Division | H1: Job Title | I1: Supervisor | J1: Cell Number | K1: Status | L1: Source Row
A2: andree@wearcheck.co.za | B2: André Erasmus | C2: WC511 | D2: ARC-TCA | E2: AFS | G2: AFS | H2: Machinery Inspector / Auditor | I2: Johan Stols | J2: 0833088571 | K2: Submitted | L2: 7
A3: antonio.ehrke@wearcheckrs.com | B3: Antonio Ehrke | C3: WC503 | D3: ARC-RCA | E3: AFS | G3: AFS | H3: RCA Inspector | I3: Roger Henwood | J3: 0834695668 | K3: Submitted | L3: 11
A4: Arnold@WearCheckRS.com | B4: Arnoldus Johannes van Zyl | C4: WC526 | D4: ARC-TCA | E4: AFS | G4: AFS | H4: Electrical Inspector | I4: Johan Stols | J4: 067412 1369 | K4: Submitted | L4: 13
A5: colleen.pyper@WearCheckRS.com | B5: Colleen Pyper | C5: WC486 | D5: AFS | E5: AFS | G5: AFS | H5: Admin and Finance Assistant | I5: Adri Ludick | J5: 0662916811 | K5: Submitted | L5: 21
A6: greeffm@wearcheck.co.za | B6: Daniel Greef Meintjies | C6: WC528 | D6: ARC-NDT | E6: AFS | G6: AFS | H6: Inspector (Lifting and NDT) | I6: Adri Ludick | J6: 0674121318 | K6: Submitted | L6: 22
A7: edwin@wearcheckrs.com | B7: Edwin Ashley Gibbons | C7: WEC138 | D7: ARC-TCA | E7: AFS | G7: AFS | H7: ARC TC Machinery Inspector | I7: Johan Stols | J7: 0725336075 | K7: Submitted | L7: 32
A8: ethel.mienie@WearCheckRS.com | B8: Ethel Mienie | C8: WC488 | D8: AFS | E8: AFS | G8: AFS | H8: Administration Assistant | I8: Adri Ludick | J8: 0660215452 | K8: Submitted | L8: 33
A9: evertv@wearcheck.co.za | B9: Evert Viljoen | C9: WC497 | D9: ARC-NDT | E9: AFS | G9: AFS | H9: Senior Machinery Inspector | I9: Adri Ludick | J9: 0795284219 | K9: Submitted | L9: 36
A10: godfreyb@wearcheck.co.za | B10: Godfrey Boikhutso | C10: WC510 | D10: ARC-TCA | E10: AFS | G10: AFS | H10: Inspector | I10: Johan Stols | J10: 0718609242 | K10: Submitted | L10: 42
A11: jacov@wearcheck.co.za | B11: Jacobus Frederick Venter | C11: WC493 | D11: ARC-NDT | E11: AFS | G11: AFS | H11: Senior Machinery Inspector | I11: Adri Ludick | J11: 0834009604 | K11: Submitted | L11: 50
A12: janb@wearcheck.co.za | B12: Jan Booysens | C12: WC496 | D12: ARC-NDT | E12: AFS | G12: AFS | H12: Senior Machinery Inspector | I12: Adri Ludick | J12: 0718665249 | K12: Submitted | L12: 54
B13: Jean Pierre du Plessis | D13: ARC-TCA | E13: AFS | G13: AFS | H13: Machinery Inspector | I13: Johan Stols | J13: 0602033229 | K13: Not Submitted | L13: 57
A14: jeanj@wearcheck.co.za | B14: Jean-Pierre Jordaan | C14: WC527 | D14: ARC-NDT | E14: AFS | G14: AFS | H14: Inspector (Lifting and NDT) | I14: Adri Ludick | J14: 0674121382 | K14: Submitted | L14: 63
A15: JohanB@wearcheckRS.com | B15: Johan Bekker | C15: WC645 | D15: ARC-TCA | E15: AFS | G15: AFS | H15: ARC TC Inspector | I15: Johan Stols | J15: 0675951633 | K15: Submitted | L15: 58
A16: johanr@wearcheckrs.com | B16: Johan Rossouw | C16: WC491 | D16: ARC-TCA | E16: AFS | G16: AFS | H16: Senior Inspector | I16: Johan Stols | J16: 0829274240 | K16: Submitted | L16: 59
A17: janniel@wearcheck.co.za | B17: Johann Louw | C17: WC494 | D17: ARC-NDT | E17: AFS | G17: AFS | H17: Inspector | I17: Adri Ludick | J17: 0718607663 | K17: Submitted | L17: 55
A18: Johans@wearcheckrs.com | B18: Johannes Gideon Francios Stols | C18: WC508 | D18: ARC-TCA | E18: AFS | G18: AFS | H18: ARC TC Manager | I18: Philip Schutte | J18: 0832943748 | K18: Submitted | L18: 60
A19: josephk@wearcheck.co.za | B19: Joseph Benjamin Kies | C19: WC531 | D19: ARC-TCA | E19: AFS | G19: AFS | H19: Machinery Inspector | I19: Johan Stols | J19: 0674121368 | K19: Submitted | L19: 62
A20: khotso@wearcheckrs.com | B20: Khotso Thabo Mosala | C20: WC482 | D20: ARC-TCA | E20: AFS | G20: AFS | H20: Inspector | I20: Johan Stols | J20: 0823321905 | K20: Submitted | L20: 65
A21: lorrainem@wearcheck.co.za | B21: Lorraine Lerato Mokgethi | C21: WC495 | D21: ARC-NDT | E21: AFS | G21: AFS | H21: Technician | I21: Adri Ludick | J21: 786 672 158 | K21: Submitted | L21: 68
A22: mervyng@wearcheck.co.za | B22: Mervyn Thomas Gibbons | C22: WC536 | D22: ARC-TCA | E22: AFS | G22: AFS | H22: ARC TC Machinery Inspector | I22: Johan Stols | J22: 0674193633 | K22: Submitted | L22: 80
A23: mikes@weacheckrs.com | B23: Mike Mbongeni Shongwe | C23: WC483 | D23: ARC-NDT | E23: AFS | G23: AFS | H23: Senior Inspector | I23: Adri Ludick | J23: 0718507077 | K23: Submitted | L23: 78
A24: nico.duplessis@wearcheckrs.com | B24: Nicolaas du Plessis | C24: WC506 | D24: ARC-RCA | E24: AFS | G24: AFS | H24: RCA Inspector | I24: Roger Henwood | J24: 0718937378 | K24: Submitted | L24: 87
A25: Landus@wearcheckrs.com | B25: Norman Landus Walters | C25: WC509 | D25: ARC-TCA | E25: AFS | G25: AFS | H25: Machinery Inspector | I25: Johan Stols | J25: 076 385 2151 | K25: Submitted | L25: 91
A26: patrick@wearcheckrs.com | B26: Patrick Nel | C26: WC498 | D26: ARC-NDT | E26: AFS | G26: AFS | H26: Machinery Inspector | I26: Adri Ludick | J26: 0723633245 | K26: Submitted | L26: 93
B27: Richard van Vuuren | C27: WC507 | E27: AFS | G27: AFS | I27: Adri Ludick | L27: 103
A28: rogerh@wearcheckrs.com | B28: Roger Henwood | C28: WC504 | D28: ARC-RCA | E28: AFS | G28: AFS | H28: RCA Operations Manager | I28: Philip Schutte | J28: 0834465155 | K28: Submitted | L28: 104
A29: rynhardt.smit@wearcheckrs.com | B29: Rynhardt Smit | C29: WC501 | D29: ARC-RCA | E29: AFS | G29: AFS | H29: RCA Inspector | I29: Roger Henwood | J29: 0833081601 | K29: Submitted | L29: 108
A30: simondifutso@WearCheckRS.com | B30: Simon Petrus Difutso | C30: WC485 | D30: ARC-NDT | E30: AFS | G30: AFS | H30: AMM Junior Management | I30: Adri Ludick | J30: 0838541915 | K30: Submitted | L30: 113
A31: teresa.venter@wearcheckRS.com | B31: Teresa Venter | C31: WC487 | D31: AFS | E31: AFS | G31: AFS | H31: Administration Assistant | I31: Adri Ludick | J31: 0662916929 | K31: Submitted | L31: 116
A32: Riaandp@wearcheckRS.com | B32: Adriaan Johannes du Plooy | C32: WC591 | D32: ARC-RCM | E32: WearCheck | F32: Mozambique | G32: Mozambique | H32: Country Manager | I32: Jaco Willer | J32: 0835965562 | K32: Submitted | L32: 101
A33: armindo@wearcheckrs.com | B33: Armindo Muchacho | C33: Unknown | D33: ARC-RCM | E33: WearCheck | F33: Mozambique | G33: Mozambique | H33: Site Supervisor | I33: Riaan du Plooy | J33: 258848349643 | K33: Submitted | L33: 12
A34: N/A | B34: Benedito Timana | C34: Unknown | D34: ARC-RCM | E34: WearCheck | F34: Mozambique | G34: Mozambique | H34: Oil Sampler / Data collector | I34: Riaan du Plooy | J34: 258 879321970 | K34: Submitted | L34: 15
A35: davidl@wearcheckrs.com | B35: David Lipague | C35: Unknown | D35: ARC-RCM | E35: WearCheck | F35: Mozambique | G35: Mozambique | H35: Reliability Technician | I35: Riaan du Plooy | J35: 258847817888 | K35: Submitted | L35: 25
A36: isac@wearcheckrs.com | B36: Isac Zacarias | C36: Unknown | D36: ARC-RCM | E36: WearCheck | F36: Mozambique | G36: Mozambique | H36: Reliability Technician | I36: Riaan du Plooy | J36: 258849439848 | K36: Submitted | L36: 49
A37: Muhamad@wearcheckRS.com | B37: Muhamad Hanif | C37: Unknown | D37: ARC-RCM | E37: WearCheck | F37: Mozambique | G37: Mozambique | H37: Reliability Technician | I37: Riaan du Plooy | J37: 258878054903 | K37: Submitted | L37: 88
A38: N/A | B38: Peter Ivo Mateus Mahlangu | D38: ARC-RCM | E38: WearCheck | F38: Mozambique | G38: Mozambique | H38: Senior Technician | I38: Riaan du Plooy | J38: 258842628215 | K38: Submitted | L38: 97
A39: Placido@wearcheckrs.com | B39: Placido Maculuve | C39: Unknown | D39: ARC-RCM | E39: WearCheck | F39: Mozambique | G39: Mozambique | H39: Senior Technician | I39: Riaan du Plooy | J39: 258845070300 | K39: Submitted | L39: 99
A40: dian@wearcheckrs.com | B40: Dian Leff | C40: WCN008 | D40: ARC-RCM | E40: WearCheck | F40: Namibia | G40: Namibia | H40: Reliability Technician | I40: Rohan Willer | J40: 0817614612 | K40: Submitted | L40: 28
...

Sheet License_Raw
A1: Display Name | B1: User Principal Name | C1: Licenses
A2: Admin | B2: admin@WearCheckRS.com | C2: Microsoft Defender for Office 365 (Plan 2)+Microsoft Fabric (Free)+Microsoft 365 E3
A3: Adri Ludick | B3: A.Ludick@WearCheckRS.com | C3: Microsoft 365 Business Premium+Microsoft Copilot Studio Viral Trial+Microsoft Defender for Office 365 (Plan 2)+Microsoft Power Automate Free
A4: Adri Ludick Old | B4: Adri.ludick@WearCheckRS.com | C4: Microsoft Defender for Office 365 (Plan 2)+Microsoft Power Automate Free+Microsoft 365 Business Standard
A5: Adriaan Bouwer | B5: adriaanb@WearCheckRS.com | C5: Microsoft Defender for Office 365 (Plan 2)+Microsoft Power Automate Free+Microsoft 365 Business Standard+Microsoft Fabric (Free)
A6: AFS Application | B6: afs_app@WearCheckRS.com | C6: Microsoft Power Automate Free+Exchange Online (Plan 1)
A7: Alex Outram | B7: Alex@WearCheckRS.com | C7: Microsoft Defender for Office 365 (Plan 2)+Microsoft Power Automate Free+Microsoft Fabric (Free)+Microsoft 365 Business Standard
A8: Allan Stuurman | B8: Allan@WearCheckRS.com | C8: Microsoft Defender for Office 365 (Plan 2)+Microsoft 365 Business Standard
A9: Andrew Robb | B9: Andrew@wearcheckrs.com | C9: Microsoft 365 Business Premium+Microsoft Defender for Office 365 (Plan 2)+Microsoft Fabric (Free)
A10: Annah Modutwane | B10: annahm@WearCheckRS.com | C10: Microsoft Defender for Office 365 (Plan 2)+Microsoft Power Automate Free+Microsoft Fabric (Free)+Microsoft 365 Business Standard
A11: Annemie Willer | B11: annemie@WearCheckRS.com | C11: Microsoft Defender for Office 365 (Plan 2)+Power BI Premium Per User+Microsoft Copilot Studio Viral Trial+Microsoft Power Apps Plan 2 Trial+Microsoft 365 E3+Microsoft Fabric (Free)+Microsoft Power Automate Free
A12: Antonio Ehrke | B12: Antonio.Ehrke@WearCheckRS.com | C12: Microsoft Defender for Office 365 (Plan 2)+Microsoft 365 Business Standard
... A148: Wihan Willer | B148: Wihan@WearCheckRS.com | C148: Microsoft Defender for Office 365 (Plan 2)+Microsoft 365 Business Standard
